Workbook

Sheet P.I
A1: # | B1: PRUEBA INICIAL
B2: Documento | C2: NOMBRE (EN MAYUSCULAS Y EN ORDEN ALFABÉTICO) | D2: PREGUNTAS COMPETENCIA LECTORA | AR2: PREGUNTAS RAZONAMIENTO LÓGICO
D3: 1 | E3: 2 | F3: 3 | G3: 4 | H3: 5 | I3: 6 | J3: 7 | K3: 8 | L3: 9 | M3: 10 | N3: 11 | O3: 12 | P3: 13 | Q3: 14 | R3: 15 | S3: 16 | T3: 17 | U3: 18 | V3: 19 | W3: 20 | X3: 21 | Y3: 22 | Z3: 23 | AA3: 24 | AB3: 25 | AC3: 26 | AD3: 27 | AE3: 28 | AF3: 29 | AG3: 30 | AH3: 31 | AI3: 32 | AJ3: 33 | AK3: 34 | AL3: 35 | AM3: 36 | AN3: 37 | AO3: 38 | AP3: 39 | AQ3: 40 | AR3: 41 | AS3: 42 | AT3: 43 | AU3: 44 | AV3: 45 | AW3: 46 | AX3: 47 | AY3: 48 | AZ3: 49 | BA3: 50 | BB3: 51 | BC3: 52 | BD3: 53 | BE3: 54 | BF3: 55 | BG3: 56 | BH3: 57 | BI3: 58 | BJ3: 59 | BK3: 60 | BL3: 61 | BM3: 62 | BN3: 63 | BO3: 64 | BP3: 65 | BQ3: 66 | BR3: 67 | BS3: 68 | BT3: 69 | BU3: 70 | BV3: 71 | BW3: 72 | BX3: 73 | BY3: 74 | BZ3: 75 | CA3: 76 | CB3: 77 | CC3: 78 | CD3: 79 | CE3: 80
C4: RESPUESTAS CORRECTAS | D4: B | E4: D | F4: D | G4: A | H4: C | I4: C | J4: A | K4: C | L4: A | M4: C | N4: B | O4: D | P4: B | Q4: C | R4: B | S4: A | T4: C | U4: C | V4: D | W4: C | X4: D | Y4: B | Z4: B | AA4: D | AB4: A | AC4: B | AD4: C | AE4: C | AF4: B | AG4: C | AH4: A | AI4: D | AJ4: A | AK4: B | AL4: C | AM4: A | AN4: B | AO4: D | AP4: C | AQ4: X | AR4: C | AS4: A | AT4: A | AU4: A | AV4: A | AW4: B | AX4: C | AY4: A | AZ4: A | BA4: A | BB4: C | BC4: D | BD4: B | BE4: B | BF4: A | BG4: B | BH4: B | BI4: C | BJ4: C | BK4: B | BL4: C | BM4: A | BN4: D | BO4: B | BP4: C | BQ4: C | BR4: D | BS4: A | BT4: A | BU4: B | BV4: C | BW4: B | BX4: B | BY4: C | BZ4: B | CA4: A | CB4: B | CC4: B | CD4: X | CE4: X
A5: 1 | B5: 1063789684 | C5: ANALÍA APARICIO | AR5: C | AS5: C | AT5: D | AU5: A | AV5: D | AW5: C | AX5: D | AY5: A | AZ5: B | BA5: C | BB5: C | BC5: B | BD5: B | BE5: B | BF5: D | BG5: D | BH5: C | BI5: D | BJ5: D | BK5: C | BL5: A | BM5: A | BN5: D | BO5: B | BP5: A | BQ5: C | BR5: C | BS5: B | BT5: D | BU5: A | BV5: C | BW5: B | BX5: B | BY5: D | BZ5: A | CA5: C | CB5: B | CC5: B
A6: 2 | B6: 0063789684 | C6: ANALÍA APARICIO HOYOS | AR6: C | AS6: A | AT6: B | AU6: A | AV6: D | AW6: A | AX6: C | AY6: D | AZ6: A | BA6: B | BB6: C | BC6: A | BD6: B | BE6: B | BF6: C | BG6: B | BH6: B | BI6: C | BJ6: C | BK6: C | BL6: D | BM6: A | BN6: B | BO6: D | BP6: D | BQ6: C | BR6: C | BS6: B | BT6: D | BU6: B | BV6: A | BW6: A | BX6: B | BY6: D | BZ6: C | CA6: C | CB6: D | CC6: A
A7: 3 | B7: 1066605744 | C7: ANDREA CAROLINA ACUÑA CORONADO | AR7: C | AS7: C | AT7: A | AU7: C | AV7: D | AW7: D | AX7: B | AY7: A | AZ7: B | BA7: D | BB7: C | BC7: B | BD7: A | BE7: B | BF7: A | BG7: D | BH7: C | BI7: C | BJ7: A | BK7: B | BL7: D | BM7: A | BN7: D | BO7: B | BP7: C | BQ7: B | BR7: C | BS7: B | BT7: A | BU7: C | BV7: C | BW7: D | BX7: B | BY7: A | BZ7: D | CA7: D | CB7: A | CC7: B
A8: 4 | B8: 1063789907 | C8: ANDREA CAROLINA TRUJILLO HERRERA | AR8: D | AS8: A | AT8: D | AU8: A | AV8: D | AW8: B | AX8: B | AY8: D | AZ8: A | BA8: A | BC8: A | BD8: A | BE8: C | BF8: D | BG8: B | BH8: A | BI8: B | BJ8: A | BK8: C | BL8: A | BM8: D | BN8: D | BO8: A | BP8: A | BQ8: B | BR8: C | BS8: C | BT8: B | BU8: C | BV8: D | BW8: B | BX8: A | BY8: D | BZ8: D | CA8: C | CB8: A | CC8: B
A9: 5 | B9: 1063359856 | C9: ANDRÉS DAVID OSUNA ALVAREZ | AR9: C | AS9: A | AT9: C | AU9: A | AV9: C | AW9: D | AX9: B | AY9: C | AZ9: A | BA9: D | BB9: B | BC9: B | BD9: C | BE9: A | BF9: D | BG9: C | BH9: A | BI9: B | BJ9: A | BK9: C | BL9: D | BM9: B | BN9: C | BO9: A | BP9: C | BQ9: A | BR9: C | BS9: A | BT9: D | BU9: B | BV9: D | BW9: B | BX9: A | BY9: A | BZ9: D | CA9: C | CB9: B | CC9: A
A10: 6 | B10: 1063370284 | C10: ANDRES EDUARDO CISNEROS MARTINEZ
A11: 7 | B11: 1063789259 | C11: ANGEL GABRIEL ARROYO ARRIETA | AR11: C | AS11: B | AT11: C | AU11: B | AV11: D | AW11: B | AX11: B | AY11: C | AZ11: B | BA11: B | BB11: D | BC11: B | BD11: B | BE11: C | BF11: A | BG11: D | BH11: D | BI11: B | BJ11: C | BK11: C | BL11: A | BM11: B | BN11: C | BO11: A | BP11: C | BQ11: B | BR11: C | BS11: A | BT11: C | BU11: A | BV11: B | BW11: C | BX11: A | BY11: C | BZ11: C | CA11: B | CB11: C | CC11: B
A12: 8 | B12: 1066604750 | C12: ANGELINA MARIA OYÓLA HERRERA | AR12: C | AS12: B | AT12: C | AU12: C | AV12: B | AW12: B | AX12: A | AY12: A | AZ12: B | BA12: B | BB12: D | BC12: B | BD12: B | BE12: C | BF12: C | BG12: C | BH12: B | BI12: C | BJ12: A | BK12: B | BL12: C | BM12: B | BN12: C | BO12: C | BP12: A | BQ12: D | BR12: B | BS12: B | BT12: C | BU12: D | BV12: C | BW12: D | BX12: B | BY12: C | BZ12: B | CA12: C | CB12: C | CC12: B
A13: 9 | B13: 1063358724 | C13: CELENY LUZ ACOSTA MONTERROSA
A14: 10 | B14: 1063290142 | C14: DARLENE TRUJILLO | AR14: D | AS14: D | AT14: A | AU14: A | AV14: D | AW14: B | AX14: C | AY14: B | AZ14: A | BA14: C | BB14: C | BC14: C | BD14: B | BE14: C | BF14: B | BG14: B | BH14: B | BI14: B | BJ14: C | BK14: C | BL14: B | BM14: A | BN14: A | BO14: B | BP14: C | BQ14: C | BR14: B | BS14: B | BT14: D | BU14: A | BV14: D | BW14: B | BX14: C | BY14: D | BZ14: B | CA14: B | CB14: D | CC14: A
A15: 11 | B15: 1063292574 | C15: DAYANA MARÍA ARGUMEDO ARRIETA | AR15: C | AS15: C | AT15: C | AU15: A | AV15: C | AW15: A | AX15: C | AY15: D | AZ15: A | BA15: C | BB15: C | BC15: B | BD15: B | BE15: C | BF15: C | BG15: A | BH15: C | BI15: C | BJ15: D | BK15: C | BL15: D | BM15: A | BN15: D | BO15: A | BP15: C | BQ15: B | BR15: B | BS15: B | BT15: B | BU15: C | BV15: D | BW15: D | BX15: B | BY15: D | BZ15: C | CA15: D | CB15: B | CC15: A
A16: 12 | B16: 1066605372 | C16: DEIVER DAVID FLORES LOPEZ | AR16: D | AS16: C | AT16: C | AU16: B | AV16: D | AW16: D | AX16: C | AY16: C | AZ16: A | BA16: D | BB16: C | BC16: B | BD16: B | BE16: B | BF16: A | BG16: C | BH16: B | BI16: B | BJ16: D | BK16: D | BL16: A | BM16: A | BN16: B | BO16: A | BP16: D | BQ16: B | BR16: C | BS16: B | BT16: D | BU16: A | BV16: C | BW16: D | BX16: A | BY16: C | BZ16: B | CA16: B | CB16: C | CC16: C
A17: 13 | B17: 1063361706 | C17: DUBERNEY JARAMILLO CAPACHERO | AR17: C | AS17: A | AT17: B | AU17: B | AV17: A | AW17: D | AX17: C | AY17: C | AZ17: A | BA17: D | BB17: C | BC17: A | BD17: B | BE17: B | BF17: A | BG17: B | BH17: B | BI17: C | BJ17: C | BK17: C | BL17: C | BM17: A | BN17: D | BO17: A | BP17: B | BQ17: C | BR17: D | BS17: B | BT17: A | BU17: B | BV17: B | BW17: B | BX17: B | BY17: C | BZ17: B | CA17: B | CB17: B | CC17: C
A18: 13 | B18: 163788493 | C18: ELKIN DARIO QUITERO URANGO
A19: 14 | B19: 1063288376 | C19: EMILYS PATRICIA OVIEDO ROMERO | AR19: C | AS19: C | AT19: B | AU19: C | AV19: D | AW19: A | AX19: C | AZ19: B | BA19: C | BB19: C | BC19: B | BD19: B | BE19: B | BF19: D | BG19: B | BH19: C | BI19: C | BJ19: A | BK19: B | BL19: D | BM19: A | BN19: D | BO19: B | BP19: C | BQ19: B | BR19: C | BS19: B | BT19: A | BU19: C | BV19: C | BW19: D | BX19: B | BY19: A | BZ19: D | CA19: D | CB19: A | CC19: B
A20: 15 | B20: 1063361689 | C20: HEELEN DANIELA PÉREZ JIMÉNEZ. | AR20: C | AS20: C | AT20: D | AU20: A | AV20: A | AW20: D | AX20: C | AY20: A | AZ20: A | BA20: D | BB20: C | BC20: C | BD20: B | BE20: B | BF20: B | BG20: C | BH20: B | BI20: C | BJ20: A | BK20: B | BL20: C | BM20: A | BN20: D | BO20: B | BP20: A | BQ20: C | BR20: D | BS20: C | BT20: C | BU20: B | BV20: D | BW20: A | BX20: C | BY20: C | BZ20: B | CA20: B | CB20: C | CC20: C
A21: 15 | B21: 1063361637 | C21: ISABELA ALVARADO JULIO | AR21: D | AS21: D | AT21: C | AU21: B | AV21: D | AW21: A | AX21: B | AY21: C | AZ21: A | BA21: B | BB21: C | BC21: A | BD21: B | BE21: B | BF21: D | BG21: B | BH21: C | BI21: C | BJ21: A | BK21: B | BL21: C | BM21: A | BN21: B | BO21: D | BP21: C | BQ21: C | BR21: B | BS21: A | BT21: A | BU21: C | BV21: B | BW21: C | BX21: B | BY21: C | BZ21: D | CA21: D | CB21: A | CC21: B
A22: 16 | B22: 1067909173 | C22: ISABELA CUITIVA ALFARO | AR22: C | AS22: B | AT22: D | AU22: A | AV22: D | AW22: C | AX22: D | AY22: A | AZ22: A | BA22: A | BB22: C | BC22: D | BD22: A | BE22: B | BF22: D | BG22: D | BH22: C | BI22: D | BJ22: D | BK22: C | BL22: A | BM22: A | BN22: D | BO22: B | BP22: A | BQ22: C | BR22: C | BS22: B | BT22: D | BU22: A | BV22: D | BW22: B | BX22: B | BY22: D | BZ22: B | CA22: C | CB22: B | CC22: C
A23: 17 | B23: 1067974289 | C23: ISLENE TEIRUMA LOBO HERNÁNDEZ
A24: 18 | B24: 1067974993 | C24: JEAN CARLOS QUIÑONES HOYOS | AR24: C | AS24: A | AT24: C | AU24: A | AV24: C | AW24: B | AX24: B | AY24: C | AZ24: B | BA24: C | BB24: C | BC24: B | BD24: B | BE24: B | BF24: D | BG24: B | BH24: C | BI24: C | BJ24: A | BK24: B | BL24: D | BM24: A | BN24: D | BO24: B | BP24: C | BQ24: B | BR24: C | BS24: B | BT24: A | BU24: C | BV24: C | BW24: D | BX24: B | BY24: A | BZ24: D | CA24: D | CB24: A | CC24: B
A25: 19 | B25: 1025659114 | C25: JORGE ANDRES ARRIETA GARCIA | AR25: C | AS25: C | AT25: A | AU25: B | AV25: A | AW25: D | AX25: C | AY25: C | AZ25: D | BA25: B | BB25: A | BC25: A | BD25: B | BE25: C | BF25: D | BG25: B | BH25: C | BI25: C | BJ25: C | BK25: B | BL25: C | BM25: B | BN25: D | BO25: A | BP25: B | BQ25: C | BR25: A | BS25: D | BT25: B | BU25: B | BV25: D | BW25: D | BX25: B | BY25: B | BZ25: C | CA25: D | CB25: B | CC25: B
A26: 19 | B26: 1068423876 | C26: JULIAN ANDRES SAENZ MOLINA | AR26: C | AS26: C | AT26: D | AU26: B | AV26: D | AW26: D | AX26: D | AY26: A | AZ26: A | BA26: A | BB26: C | BC26: C | BD26: B | BE26: C | BF26: C | BG26: D | BH26: C | BI26: C | BJ26: D | BK26: B | BL26: B | BM26: A | BN26: D | BO26: B | BP26: D | BQ26: B | BR26: C | BS26: B | BT26: D | BU26: A | BV26: D | BW26: B | BX26: B | BY26: D | BZ26: C | CA26: C | CB26: D | CC26: A
A27: 20 | B27: 1067909383 | C27: JUNIOR ANDRES CALLE SAMARRA | AR27: D | AS27: C | AT27: A | AU27: C | AV27: D | AW27: A | AX27: B | AY27: A | AZ27: A | BA27: A | BB27: D | BC27: D | BD27: A | BE27: B | BF27: C | BG27: A | BH27: D | BI27: C | BJ27: D | BK27: B | BL27: D | BM27: A | BN27: C | BO27: D | BP27: A | BQ27: C | BR27: B | BS27: B | BT27: D | BU27: C | BV27: A | BW27: D | BX27: C | BY27: C | BZ27: A | CA27: C | CB27: D | CC27: B
A28: 21 | B28: 1063789915 | C28: KAREN NOEMITH NIETO DE AGUAS | AR28: C | AS28: B | AT28: D | AU28: C | AV28: D | AW28: B | AX28: C | AY28: A | AZ28: B | BA28: B | BB28: D | BC28: B | BD28: B | BE28: C | BF28: D | BG28: C | BH28: B | BI28: C | BJ28: A | BK28: B | BL28: C | BM28: B | BN28: C | BO28: C | BP28: A | BQ28: D | BR28: B | BS28: A | BT28: C | BU28: D | BV28: C | BW28: D | BX28: A | BY28: C | BZ28: B | CA28: D | CB28: B | CC28: B
A29: 22 | B29: 1063790077 | C29: KATERINE HOLGUIN BENAVIDES | AR29: C | AS29: B | AT29: D | AU29: C | AV29: D | AW29: B | AX29: C | AY29: A | AZ29: B | BA29: B | BB29: D | BC29: B | BD29: B | BE29: C | BF29: D | BG29: C | BH29: B | BI29: C | BJ29: A | BK29: B | BL29: C | BM29: B | BN29: C | BO29: C | BP29: A | BQ29: C | BR29: B | BS29: C | BT29: B | BU29: C | BV29: C | BW29: B | BX29: A | BY29: B | BZ29: B | CA29: D | CB29: B | CC29: B
A30: 23 | B30: 1063789697 | C30: KATIA ANDREA FERNÁNDEZ RAMOS
A31: 24 | B31: 1063360877 | C31: KEIDER LUIS SUAREZ CALDEÑO | AR31: C | AS31: C | AT31: A | AU31: B | AV31: A | AW31: D | AX31: C | AY31: C | AZ31: B | BA31: B | BB31: D | BC31: B | BD31: B | BE31: C | BF31: D | BG31: C | BH31: B | BI31: C | BJ31: A | BK31: B | BL31: C | BM31: B | BN31: C | BO31: C | BP31: A | BQ31: D | BR31: B | BS31: A | BT31: C | BU31: D | BV31: C | BW31: D | BX31: A | BY31: C | BZ31: B | CA31: D | CB31: B | CC31: B
A32: 25 | B32: 1068584743 | C32: KEINER NICK TUIRAN CUITIVA
A33: 26 | B33: 1066606047 | C33: KENDIS ESTER MONTIEL VILLALOBOS | AR33: C | AS33: A | AT33: D | AU33: A | AV33: A | AW33: D | AX33: C | AY33: A | AZ33: A | BA33: A | BB33: C | BC33: B | BD33: B | BE33: B | BF33: A | BG33: B | BH33: D | BI33: C | BJ33: C | BK33: D | BL33: B | BM33: B | BN33: D | BO33: B | BP33: A | BQ33: D | BR33: C | BS33: B | BT33: A | BU33: A | BV33: C | BW33: D | BX33: A | BY33: D | BZ33: B | CA33: B | CB33: B | CC33: B
A34: 27 | B34: 1063361381 | C34: KEVIN DAVID ACOSTA RAMOS | AR34: D | AS34: C | AT34: C | AU34: B | AV34: A | AW34: D | AX34: C | AY34: B | AZ34: A | BA34: D | BB34: B | BC34: A | BD34: B | BE34: C | BF34: A | BG34: D | BH34: C | BI34: D | BJ34: B | BK34: A | BL34: C | BM34: A | BN34: D | BO34: C | BP34: A | BQ34: B | BR34: D | BS34: B | BT34: C | BU34: A | BV34: C | BW34: B | BX34: D | BY34: A | BZ34: B | CA34: C | CB34: D | CC34: D
A35: 28 | B35: 1062969472 | C35: LENIS ENITH ORTEGA FUENTES
A36: 29 | B36: 1063789816 | C36: LILIANA ÁLVAREZ FLÓREZ | AR36: D | AS36: A | AT36: A | AU36: A | AV36: D | AW36: A | AX36: C | AY36: C | AZ36: C | BA36: A | BB36: D | BC36: A | BD36: B | BE36: B | BF36: A | BG36: C | BH36: B | BI36: C | BJ36: D | BK36: C | BL36: B | BM36: A | BN36: C | BO36: C | BP36: B | BQ36: A | BR36: C | BS36: D | BT36: A | BU36: B | BV36: B | BW36: A | BX36: C | BY36: A | BZ36: B | CA36: B | CB36: A | CC36: C
A37: 30 | B37: 1064193447 | C37: LUISA FERNANDA VILORIA VASQUEZ | AR37: C | AS37: C | AT37: C | AU37: C | AV37: C | AW37: C | AX37: D | AY37: C | AZ37: D | BA37: A | BB37: C | BC37: A | BD37: B | BE37: C | BF37: D | BG37: C | BH37: C | BI37: C | BJ37: D | BK37: D | BL37: A | BM37: A | BN37: D | BO37: A | BP37: B | BQ37: B | BR37: C | BS37: C | BT37: B | BU37: A | BV37: B | BW37: C | BX37: A | BY37: C | BZ37: C | CA37: B | CB37: C | CC37: C
A38: 31 | B38: 1063288993 | C38: MARÍA ISABEL QUIÑONES HERNÁNDEZ | AR38: C | AS38: A | AT38: B | AU38: B | AV38: D | AW38: D | AX38: C | AY38: B | AZ38: A | BA38: A | BB38: C | BC38: C | BD38: B | BE38: C | BF38: D | BG38: A | BH38: C | BI38: A | BJ38: D | BK38: C | BL38: A | BM38: A | BN38: B | BO38: C | BP38: A | BQ38: A | BR38: B | BS38: C | BT38: A | BU38: B | BV38: A | BW38: C | BX38: D | BY38: B | BZ38: C | CA38: D | CB38: B | CC38: C
A39: 32 | B39: 1062438199 | C39: MARÍA JOSEFINA MONTIEL BARRETO
A40: 33 | B40: 1066605849 | C40: MICHELL GONZALEZ SEVERICHE
...

Sheet Conv. PI
A1: # | B1: PRUEBA INICIAL | CE1: CONSOLIDADO CL | CF1: NOTA CL | CG1: NOTA TOTAL 0-5 CL | CH1: CONSOLIDADO RL | CI1: NOTA RL | CJ1: NOTA TOTAL 0-5 RL | CK1: CONSOLIDADO TOTAL | CL1: NOTA TOTAL | CM1: NOTA TOTAL 0-5
B2: NOMBRE | C2: PREGUNTAS RL | AQ2: PREGUNTAS CL
C3: 1 | D3: 2 | E3: 3 | F3: 4 | G3: 5 | H3: 6 | I3: 7 | J3: 8 | K3: 9 | L3: 10 | M3: 11 | N3: 12 | O3: 13 | P3: 14 | Q3: 15 | R3: 16 | S3: 17 | T3: 18 | U3: 19 | V3: 20 | W3: 21 | X3: 22 | Y3: 23 | Z3: 24 | AA3: 25 | AB3: 26 | AC3: 27 | AD3: 28 | AE3: 29 | AF3: 30 | AG3: 31 | AH3: 32 | AI3: 33 | AJ3: 34 | AK3: 35 | AL3: 36 | AM3: 37 | AN3: 38 | AO3: 39 | AP3: 40 | AQ3: 41 | AR3: 42 | AS3: 43 | AT3: 44 | AU3: 45 | AV3: 46 | AW3: 47 | AX3: 48 | AY3: 49 | AZ3: 50 | BA3: 51 | BB3: 52 | BC3: 53 | BD3: 54 | BE3: 55 | BF3: 56 | BG3: 57 | BH3: 58 | BI3: 59 | BJ3: 60 | BK3: 61 | BL3: 62 | BM3: 63 | BN3: 64 | BO3: 65 | BP3: 66 | BQ3: 67 | BR3: 68 | BS3: 69 | BT3: 70 | BU3: 71 | BV3: 72 | BW3: 73 | BX3: 74 | BY3: 75 | BZ3: 76 | CA3: 77 | CB3: 78 | CC3: 79 | CD3: 80 | CF3: 39 | CI3: 38 | CL3: =+CF3+CI3 -> 77
B4: RESPUESTAS CORRECTAS
A5: 1 | B5: =P.I!C5 -> ANALÍA APARICIO | C5: =+IF(P.I!D5=P.I!$D$4,1,0) -> 0 | D5: =+IF(P.I!E5=P.I!$E$4,1,0) -> 0 | E5: =+IF(P.I!F5=P.I!$F$4,1,0) -> 0 | F5: =+IF(P.I!G5=P.I!$G$4,1,0) -> 0 | G5: =+IF(P.I!H5=P.I!$H$4,1,0) -> 0 | H5: =+IF(P.I!I5=P.I!$I$4,1,0) -> 0 | I5: =+IF(P.I!J5=P.I!$J$4,1,0) -> 0 | J5: =+IF(P.I!K5=P.I!$K$4,1,0) -> 0 | K5: =+IF(P.I!L5=P.I!$L$4,1,0) -> 0 | L5: =+IF(P.I!M5=P.I!$M$4,1,0) -> 0 | M5: =+IF(P.I!N5=P.I!$N$4,1,0) -> 0 | N5: =+IF(P.I!O5=P.I!$O$4,1,0) -> 0 | O5: =+IF(P.I!P5=P.I!$P$4,1,0) -> 0 | P5: =+IF(P.I!Q5=P.I!$Q$4,1,0) -> 0 | Q5: =+IF(P.I!R5=P.I!$R$4,1,0) -> 0 | R5: =+IF(P.I!S5=P.I!$S$4,1,0) -> 0 | S5: =+IF(P.I!T5=P.I!$T$4,1,0) -> 0 | T5: =+IF(P.I!U5=P.I!$U$4,1,0) -> 0 | U5: =+IF(P.I!V5=P.I!$V$4,1,0) -> 0 | V5: =+IF(P.I!W5=P.I!$W$4,1,0) -> 0 | W5: =+IF(P.I!X5=P.I!$X$4,1,0) -> 0 | X5: =+IF(P.I!Y5=P.I!$Y$4,1,0) -> 0 | Y5: =+IF(P.I!Z5=P.I!$Z$4,1,0) -> 0 | Z5: =+IF(P.I!AA5=P.I!$AA$4,1,0) -> 0 | AA5: =+IF(P.I!AB5=P.I!$AB$4,1,0) -> 0 | AB5: =+IF(P.I!AC5=P.I!$AC$4,1,0) -> 0 | AC5: =+IF(P.I!AD5=P.I!$AD$4,1,0) -> 0 | AD5: =+IF(P.I!AE5=P.I!$AE$4,1,0) -> 0 | AE5: =+IF(P.I!AF5=P.I!$AF$4,1,0) -> 0 | AF5: =+IF(P.I!AG5=P.I!$AG$4,1,0) -> 0 | AG5: =+IF(P.I!AH5=P.I!$AH$4,1,0) -> 0 | AH5: =+IF(P.I!AI5=P.I!$AI$4,1,0) -> 0 | AI5: =+IF(P.I!AJ5=P.I!$AJ$4,1,0) -> 0 | AJ5: =+IF(P.I!AK5=P.I!$AK$4,1,0) -> 0 | AK5: =+IF(P.I!AL5=P.I!$AL$4,1,0) -> 0 | AL5: =+IF(P.I!AM5=P.I!$AM$4,1,0) -> 0 | AM5: =+IF(P.I!AN5=P.I!$AN$4,1,0) -> 0 | AN5: =+IF(P.I!AO5=P.I!$AO$4,1,0) -> 0 | AO5: =+IF(P.I!AP5=P.I!$AP$4,1,0) -> 0 | AP5: =+IF(P.I!AQ5=P.I!$AQ$4,1,0) -> 0 | AQ5: =+IF(P.I!AR5=P.I!$AR$4,1,0) -> 1 | AR5: =+IF(P.I!AS5=P.I!$AS$4,1,0) -> 0 | AS5: =+IF(P.I!AT5=P.I!$AT$4,1,0) -> 0 | AT5: =+IF(P.I!AU5=P.I!$AU$4,1,0) -> 1 | AU5: =+IF(P.I!AV5=P.I!$AV$4,1,0) -> 0 | AV5: =+IF(P.I!AW5=P.I!$AW$4,1,0) -> 0 | AW5: =+IF(P.I!AX5=P.I!$AX$4,1,0) -> 0 | AX5: =+IF(P.I!AY5=P.I!$AY$4,1,0) -> 1 | AY5: =+IF(P.I!AZ5=P.I!$AZ$4,1,0) -> 0 | AZ5: =+IF(P.I!BA5=P.I!$BA$4,1,0) -> 0 | BA5: =+IF(P.I!BB5=P.I!$BB$4,1,0) -> 1 | BB5: =+IF(P.I!BC5=P.I!$BC$4,1,0) -> 0 | BC5: =+IF(P.I!BD5=P.I!$BD$4,1,0) -> 1 | BD5: =+IF(P.I!BE5=P.I!$BE$4,1,0) -> 1 | BE5: =+IF(P.I!BF5=P.I!$BF$4,1,0) -> 0 | BF5: =+IF(P.I!BG5=P.I!$BG$4,1,0) -> 0 | BG5: =+IF(P.I!BH5=P.I!$BH$4,1,0) -> 0 | BH5: =+IF(P.I!BI5=P.I!$BI$4,1,0) -> 0 | BI5: =+IF(P.I!BJ5=P.I!$BJ$4,1,0) -> 0 | BJ5: =+IF(P.I!BK5=P.I!$BK$4,1,0) -> 0 | BK5: =+IF(P.I!BL5=P.I!$BL$4,1,0) -> 0 | BL5: =+IF(P.I!BM5=P.I!$BM$4,1,0) -> 1 | BM5: =+IF(P.I!BN5=P.I!$BN$4,1,0) -> 1 | BN5: =+IF(P.I!BO5=P.I!$BO$4,1,0) -> 1 | BO5: =+IF(P.I!BP5=P.I!$BP$4,1,0) -> 0 | BP5: =+IF(P.I!BQ5=P.I!$BQ$4,1,0) -> 1 | BQ5: =+IF(P.I!BR5=P.I!$BR$4,1,0) -> 0 | BR5: =+IF(P.I!BS5=P.I!$BS$4,1,0) -> 0 | BS5: =+IF(P.I!BT5=P.I!$BT$4,1,0) -> 0 | BT5: =+IF(P.I!BU5=P.I!$BU$4,1,0) -> 0 | BU5: =+IF(P.I!BV5=P.I!$BV$4,1,0) -> 1 | BV5: =+IF(P.I!BW5=P.I!$BW$4,1,0) -> 1 | BW5: =+IF(P.I!BX5=P.I!$BX$4,1,0) -> 1 | BX5: =+IF(P.I!BY5=P.I!$BY$4,1,0) -> 0 | BY5: =+IF(P.I!BZ5=P.I!$BZ$4,1,0) -> 0 | BZ5: =+IF(P.I!CA5=P.I!$CA$4,1,0) -> 0 | CA5: =+IF(P.I!CB5=P.I!$CB$4,1,0) -> 1 | CB5: =+IF(P.I!CC5=P.I!$CC$4,1,0) -> 1 | CC5: =+IF(P.I!CD5=P.I!$CD$4,1,0) -> 0 | CD5: =+IF(P.I!CE5=P.I!$CE$4,1,0) -> 0 | CE5: =+SUM(C5:AP5) -> 0 | CF5: =+CE5/$CF$3*100 -> 0 | CG5: =+CF5*5/100 -> 0 | CH5: =+SUM(AQ5:CD5) -> 15 | CI5: =+CH5/$CI$3*100 -> 39.473684 | CJ5: =+CI5*5/100 -> 1.9736842 | CK5: =+CE5+CH5 -> 15 | CL5: =+CK5/$CL$3*100 -> 19.480519 | CM5: =+CL5*5/100 -> 0.97402597
A6: 2 | B6: =P.I!C6 -> ANALÍA APARICIO HOYOS | C6: =+IF(P.I!D6=P.I!$D$4,1,0) -> 0 | D6: =+IF(P.I!E6=P.I!$E$4,1,0) -> 0 | E6: =+IF(P.I!F6=P.I!$F$4,1,0) -> 0 | F6: =+IF(P.I!G6=P.I!$G$4,1,0) -> 0 | G6: =+IF(P.I!H6=P.I!$H$4,1,0) -> 0 | H6: =+IF(P.I!I6=P.I!$I$4,1,0) -> 0 | I6: =+IF(P.I!J6=P.I!$J$4,1,0) -> 0 | J6: =+IF(P.I!K6=P.I!$K$4,1,0) -> 0 | K6: =+IF(P.I!L6=P.I!$L$4,1,0) -> 0 | L6: =+IF(P.I!M6=P.I!$M$4,1,0) -> 0 | M6: =+IF(P.I!N6=P.I!$N$4,1,0) -> 0 | N6: =+IF(P.I!O6=P.I!$O$4,1,0) -> 0 | O6: =+IF(P.I!P6=P.I!$P$4,1,0) -> 0 | P6: =+IF(P.I!Q6=P.I!$Q$4,1,0) -> 0 | Q6: =+IF(P.I!R6=P.I!$R$4,1,0) -> 0 | R6: =+IF(P.I!S6=P.I!$S$4,1,0) -> 0 | S6: =+IF(P.I!T6=P.I!$T$4,1,0) -> 0 | T6: =+IF(P.I!U6=P.I!$U$4,1,0) -> 0 | U6: =+IF(P.I!V6=P.I!$V$4,1,0) -> 0 | V6: =+IF(P.I!W6=P.I!$W$4,1,0) -> 0 | W6: =+IF(P.I!X6=P.I!$X$4,1,0) -> 0 | X6: =+IF(P.I!Y6=P.I!$Y$4,1,0) -> 0 | Y6: =+IF(P.I!Z6=P.I!$Z$4,1,0) -> 0 | Z6: =+IF(P.I!AA6=P.I!$AA$4,1,0) -> 0 | AA6: =+IF(P.I!AB6=P.I!$AB$4,1,0) -> 0 | AB6: =+IF(P.I!AC6=P.I!$AC$4,1,0) -> 0 | AC6: =+IF(P.I!AD6=P.I!$AD$4,1,0) -> 0 | AD6: =+IF(P.I!AE6=P.I!$AE$4,1,0) -> 0 | AE6: =+IF(P.I!AF6=P.I!$AF$4,1,0) -> 0 | AF6: =+IF(P.I!AG6=P.I!$AG$4,1,0) -> 0 | AG6: =+IF(P.I!AH6=P.I!$AH$4,1,0) -> 0 | AH6: =+IF(P.I!AI6=P.I!$AI$4,1,0) -> 0 | AI6: =+IF(P.I!AJ6=P.I!$AJ$4,1,0) -> 0 | AJ6: =+IF(P.I!AK6=P.I!$AK$4,1,0) -> 0 | AK6: =+IF(P.I!AL6=P.I!$AL$4,1,0) -> 0 | AL6: =+IF(P.I!AM6=P.I!$AM$4,1,0) -> 0 | AM6: =+IF(P.I!AN6=P.I!$AN$4,1,0) -> 0 | AN6: =+IF(P.I!AO6=P.I!$AO$4,1,0) -> 0 | AO6: =+IF(P.I!AP6=P.I!$AP$4,1,0) -> 0 | AP6: =+IF(P.I!AQ6=P.I!$AQ$4,1,0) -> 0 | AQ6: =+IF(P.I!AR6=P.I!$AR$4,1,0) -> 1 | AR6: =+IF(P.I!AS6=P.I!$AS$4,1,0) -> 1 | AS6: =+IF(P.I!AT6=P.I!$AT$4,1,0) -> 0 | AT6: =+IF(P.I!AU6=P.I!$AU$4,1,0) -> 1 | AU6: =+IF(P.I!AV6=P.I!$AV$4,1,0) -> 0 | AV6: =+IF(P.I!AW6=P.I!$AW$4,1,0) -> 0 | AW6: =+IF(P.I!AX6=P.I!$AX$4,1,0) -> 1 | AX6: =+IF(P.I!AY6=P.I!$AY$4,1,0) -> 0 | AY6: =+IF(P.I!AZ6=P.I!$AZ$4,1,0) -> 1 | AZ6: =+IF(P.I!BA6=P.I!$BA$4,1,0) -> 0 | BA6: =+IF(P.I!BB6=P.I!$BB$4,1,0) -> 1 | BB6: =+IF(P.I!BC6=P.I!$BC$4,1,0) -> 0 | BC6: =+IF(P.I!BD6=P.I!$BD$4,1,0) -> 1 | BD6: =+IF(P.I!BE6=P.I!$BE$4,1,0) -> 1 | BE6: =+IF(P.I!BF6=P.I!$BF$4,1,0) -> 0 | BF6: =+IF(P.I!BG6=P.I!$BG$4,1,0) -> 1 | BG6: =+IF(P.I!BH6=P.I!$BH$4,1,0) -> 1 | BH6: =+IF(P.I!BI6=P.I!$BI$4,1,0) -> 1 | BI6: =+IF(P.I!BJ6=P.I!$BJ$4,1,0) -> 1 | BJ6: =+IF(P.I!BK6=P.I!$BK$4,1,0) -> 0 | BK6: =+IF(P.I!BL6=P.I!$BL$4,1,0) -> 0 | BL6: =+IF(P.I!BM6=P.I!$BM$4,1,0) -> 1 | BM6: =+IF(P.I!BN6=P.I!$BN$4,1,0) -> 0 | BN6: =+IF(P.I!BO6=P.I!$BO$4,1,0) -> 0 | BO6: =+IF(P.I!BP6=P.I!$BP$4,1,0) -> 0 | BP6: =+IF(P.I!BQ6=P.I!$BQ$4,1,0) -> 1 | BQ6: =+IF(P.I!BR6=P.I!$BR$4,1,0) -> 0 | BR6: =+IF(P.I!BS6=P.I!$BS$4,1,0) -> 0 | BS6: =+IF(P.I!BT6=P.I!$BT$4,1,0) -> 0 | BT6: =+IF(P.I!BU6=P.I!$BU$4,1,0) -> 1 | BU6: =+IF(P.I!BV6=P.I!$BV$4,1,0) -> 0 | BV6: =+IF(P.I!BW6=P.I!$BW$4,1,0) -> 0 | BW6: =+IF(P.I!BX6=P.I!$BX$4,1,0) -> 1 | BX6: =+IF(P.I!BY6=P.I!$BY$4,1,0) -> 0 | BY6: =+IF(P.I!BZ6=P.I!$BZ$4,1,0) -> 0 | BZ6: =+IF(P.I!CA6=P.I!$CA$4,1,0) -> 0 | CA6: =+IF(P.I!CB6=P.I!$CB$4,1,0) -> 0 | CB6: =+IF(P.I!CC6=P.I!$CC$4,1,0) -> 0 | CC6: =+IF(P.I!CD6=P.I!$CD$4,1,0) -> 0 | CD6: =+IF(P.I!CE6=P.I!$CE$4,1,0) -> 0 | CE6: =+SUM(C6:AP6) -> 0 | CF6: =+CE6/$CF$3*100 -> 0 | CG6: =+CF6*5/100 -> 0 | CH6: =+SUM(AQ6:CD6) -> 16 | CI6: =+CH6/$CI$3*100 -> 42.105263 | CJ6: =+CI6*5/100 -> 2.1052632 | CK6: =+CE6+CH6 -> 16 | CL6: =+CK6/$CL$3*100 -> 20.779221 | CM6: =+CL6*5/100 -> 1.038961
A7: 3 | B7: =P.I!#REF! -> #REF! | C7: =+IF(P.I!#REF!=P.I!$D$4,1,0) -> #REF! | D7: =+IF(P.I!#REF!=P.I!$E$4,1,0) -> #REF! | E7: =+IF(P.I!#REF!=P.I!$F$4,1,0) -> #REF! | F7: =+IF(P.I!#REF!=P.I!$G$4,1,0) -> #REF! | G7: =+IF(P.I!#REF!=P.I!$H$4,1,0) -> #REF! | H7: =+IF(P.I!#REF!=P.I!$I$4,1,0) -> #REF! | I7: =+IF(P.I!#REF!=P.I!$J$4,1,0) -> #REF! | J7: =+IF(P.I!#REF!=P.I!$K$4,1,0) -> #REF! | K7: =+IF(P.I!#REF!=P.I!$L$4,1,0) -> #REF! | L7: =+IF(P.I!#REF!=P.I!$M$4,1,0) -> #REF! | M7: =+IF(P.I!#REF!=P.I!$N$4,1,0) -> #REF! | N7: =+IF(P.I!#REF!=P.I!$O$4,1,0) -> #REF! | O7: =+IF(P.I!#REF!=P.I!$P$4,1,0) -> #REF! | P7: =+IF(P.I!#REF!=P.I!$Q$4,1,0) -> #REF! | Q7: =+IF(P.I!#REF!=P.I!$R$4,1,0) -> #REF! | R7: =+IF(P.I!#REF!=P.I!$S$4,1,0) -> #REF! | S7: =+IF(P.I!#REF!=P.I!$T$4,1,0) -> #REF! | T7: =+IF(P.I!#REF!=P.I!$U$4,1,0) -> #REF! | U7: =+IF(P.I!#REF!=P.I!$V$4,1,0) -> #REF! | V7: =+IF(P.I!#REF!=P.I!$W$4,1,0) -> #REF! | W7: =+IF(P.I!#REF!=P.I!$X$4,1,0) -> #REF! | X7: =+IF(P.I!#REF!=P.I!$Y$4,1,0) -> #REF! | Y7: =+IF(P.I!#REF!=P.I!$Z$4,1,0) -> #REF! | Z7: =+IF(P.I!#REF!=P.I!$AA$4,1,0) -> #REF! | AA7: =+IF(P.I!#REF!=P.I!$AB$4,1,0) -> #REF! | AB7: =+IF(P.I!#REF!=P.I!$AC$4,1,0) -> #REF! | AC7: =+IF(P.I!#REF!=P.I!$AD$4,1,0) -> #REF! | AD7: =+IF(P.I!#REF!=P.I!$AE$4,1,0) -> #REF! | AE7: =+IF(P.I!#REF!=P.I!$AF$4,1,0) -> #REF! | AF7: =+IF(P.I!#REF!=P.I!$AG$4,1,0) -> #REF! | AG7: =+IF(P.I!#REF!=P.I!$AH$4,1,0) -> #REF! | AH7: =+IF(P.I!#REF!=P.I!$AI$4,1,0) -> #REF! | AI7: =+IF(P.I!#REF!=P.I!$AJ$4,1,0) -> #REF! | AJ7: =+IF(P.I!#REF!=P.I!$AK$4,1,0) -> #REF! | AK7: =+IF(P.I!#REF!=P.I!$AL$4,1,0) -> #REF! | AL7: =+IF(P.I!#REF!=P.I!$AM$4,1,0) -> #REF! | AM7: =+IF(P.I!#REF!=P.I!$AN$4,1,0) -> #REF! | AN7: =+IF(P.I!#REF!=P.I!$AO$4,1,0) -> #REF! | AO7: =+IF(P.I!#REF!=P.I!$AP$4,1,0) -> #REF! | AP7: =+IF(P.I!AQ7=P.I!$AQ$4,1,0) -> 0 | AQ7: =+IF(P.I!AR7=P.I!$AR$4,1,0) -> 1 | AR7: =+IF(P.I!AS7=P.I!$AS$4,1,0) -> 0 | AS7: =+IF(P.I!AT7=P.I!$AT$4,1,0) -> 1 | AT7: =+IF(P.I!AU7=P.I!$AU$4,1,0) -> 0 | AU7: =+IF(P.I!AV7=P.I!$AV$4,1,0) -> 0 | AV7: =+IF(P.I!AW7=P.I!$AW$4,1,0) -> 0 | AW7: =+IF(P.I!AX7=P.I!$AX$4,1,0) -> 0 | AX7: =+IF(P.I!AY7=P.I!$AY$4,1,0) -> 1 | AY7: =+IF(P.I!AZ7=P.I!$AZ$4,1,0) -> 0 | AZ7: =+IF(P.I!BA7=P.I!$BA$4,1,0) -> 0 | BA7: =+IF(P.I!BB7=P.I!$BB$4,1,0) -> 1 | BB7: =+IF(P.I!BC7=P.I!$BC$4,1,0) -> 0 | BC7: =+IF(P.I!BD7=P.I!$BD$4,1,0) -> 0 | BD7: =+IF(P.I!BE7=P.I!$BE$4,1,0) -> 1 | BE7: =+IF(P.I!BF7=P.I!$BF$4,1,0) -> 1 | BF7: =+IF(P.I!BG7=P.I!$BG$4,1,0) -> 0 | BG7: =+IF(P.I!BH7=P.I!$BH$4,1,0) -> 0 | BH7: =+IF(P.I!BI7=P.I!$BI$4,1,0) -> 1 | BI7: =+IF(P.I!BJ7=P.I!$BJ$4,1,0) -> 0 | BJ7: =+IF(P.I!BK7=P.I!$BK$4,1,0) -> 1 | BK7: =+IF(P.I!BL7=P.I!$BL$4,1,0) -> 0 | BL7: =+IF(P.I!BM7=P.I!$BM$4,1,0) -> 1 | BM7: =+IF(P.I!BN7=P.I!$BN$4,1,0) -> 1 | BN7: =+IF(P.I!BO7=P.I!$BO$4,1,0) -> 1 | BO7: =+IF(P.I!BP7=P.I!$BP$4,1,0) -> 1 | BP7: =+IF(P.I!BQ7=P.I!$BQ$4,1,0) -> 0 | BQ7: =+IF(P.I!BR7=P.I!$BR$4,1,0) -> 0 | BR7: =+IF(P.I!BS7=P.I!$BS$4,1,0) -> 0 | BS7: =+IF(P.I!BT7=P.I!$BT$4,1,0) -> 1 | BT7: =+IF(P.I!BU7=P.I!$BU$4,1,0) -> 0 | BU7: =+IF(P.I!BV7=P.I!$BV$4,1,0) -> 1 | BV7: =+IF(P.I!BW7=P.I!$BW$4,1,0) -> 0 | BW7: =+IF(P.I!BX7=P.I!$BX$4,1,0) -> 1 | BX7: =+IF(P.I!BY7=P.I!$BY$4,1,0) -> 0 | BY7: =+IF(P.I!BZ7=P.I!$BZ$4,1,0) -> 0 | BZ7: =+IF(P.I!CA7=P.I!$CA$4,1,0) -> 0 | CA7: =+IF(P.I!CB7=P.I!$CB$4,1,0) -> 0 | CB7: =+IF(P.I!CC7=P.I!$CC$4,1,0) -> 1 | CC7: =+IF(P.I!CD7=P.I!$CD$4,1,0) -> 0 | CD7: =+IF(P.I!CE7=P.I!$CE$4,1,0) -> 0 | CE7: =+SUM(C7:AP7) -> #REF! | CF7: =+CE7/$CF$3*100 -> #REF! | CG7: =+CF7*5/100 -> #REF! | CH7: =+SUM(AQ7:CD7) -> 16 | CI7: =+CH7/$CI$3*100 -> 42.105263 | CJ7: =+CI7*5/100 -> 2.1052632 | CK7: =+CE7+CH7 -> #REF! | CL7: =+CK7/$CL$3*100 -> #REF! | CM7: =+CL7*5/100 -> #REF!
A8: 4 | B8: =P.I!C7 -> ANDREA CAROLINA ACUÑA CORONADO | C8: =+IF(P.I!D7=P.I!$D$4,1,0) -> 0 | D8: =+IF(P.I!E7=P.I!$E$4,1,0) -> 0 | E8: =+IF(P.I!F7=P.I!$F$4,1,0) -> 0 | F8: =+IF(P.I!G7=P.I!$G$4,1,0) -> 0 | G8: =+IF(P.I!H7=P.I!$H$4,1,0) -> 0 | H8: =+IF(P.I!I7=P.I!$I$4,1,0) -> 0 | I8: =+IF(P.I!J7=P.I!$J$4,1,0) -> 0 | J8: =+IF(P.I!K7=P.I!$K$4,1,0) -> 0 | K8: =+IF(P.I!L7=P.I!$L$4,1,0) -> 0 | L8: =+IF(P.I!M7=P.I!$M$4,1,0) -> 0 | M8: =+IF(P.I!N7=P.I!$N$4,1,0) -> 0 | N8: =+IF(P.I!O7=P.I!$O$4,1,0) -> 0 | O8: =+IF(P.I!P7=P.I!$P$4,1,0) -> 0 | P8: =+IF(P.I!Q7=P.I!$Q$4,1,0) -> 0 | Q8: =+IF(P.I!R7=P.I!$R$4,1,0) -> 0 | R8: =+IF(P.I!S7=P.I!$S$4,1,0) -> 0 | S8: =+IF(P.I!T7=P.I!$T$4,1,0) -> 0 | T8: =+IF(P.I!U7=P.I!$U$4,1,0) -> 0 | U8: =+IF(P.I!V7=P.I!$V$4,1,0) -> 0 | V8: =+IF(P.I!W7=P.I!$W$4,1,0) -> 0 | W8: =+IF(P.I!X7=P.I!$X$4,1,0) -> 0 | X8: =+IF(P.I!Y7=P.I!$Y$4,1,0) -> 0 | Y8: =+IF(P.I!Z7=P.I!$Z$4,1,0) -> 0 | Z8: =+IF(P.I!AA7=P.I!$AA$4,1,0) -> 0 | AA8: =+IF(P.I!AB7=P.I!$AB$4,1,0) -> 0 | AB8: =+IF(P.I!AC7=P.I!$AC$4,1,0) -> 0 | AC8: =+IF(P.I!AD7=P.I!$AD$4,1,0) -> 0 | AD8: =+IF(P.I!AE7=P.I!$AE$4,1,0) -> 0 | AE8: =+IF(P.I!AF7=P.I!$AF$4,1,0) -> 0 | AF8: =+IF(P.I!AG7=P.I!$AG$4,1,0) -> 0 | AG8: =+IF(P.I!AH7=P.I!$AH$4,1,0) -> 0 | AH8: =+IF(P.I!AI7=P.I!$AI$4,1,0) -> 0 | AI8: =+IF(P.I!AJ7=P.I!$AJ$4,1,0) -> 0 | AJ8: =+IF(P.I!AK7=P.I!$AK$4,1,0) -> 0 | AK8: =+IF(P.I!AL7=P.I!$AL$4,1,0) -> 0 | AL8: =+IF(P.I!AM7=P.I!$AM$4,1,0) -> 0 | AM8: =+IF(P.I!AN7=P.I!$AN$4,1,0) -> 0 | AN8: =+IF(P.I!AO7=P.I!$AO$4,1,0) -> 0 | AO8: =+IF(P.I!AP7=P.I!$AP$4,1,0) -> 0 | AP8: =+IF(P.I!AQ8=P.I!$AQ$4,1,0) -> 0 | AQ8: =+IF(P.I!AR8=P.I!$AR$4,1,0) -> 0 | AR8: =+IF(P.I!AS8=P.I!$AS$4,1,0) -> 1 | AS8: =+IF(P.I!AT8=P.I!$AT$4,1,0) -> 0 | AT8: =+IF(P.I!AU8=P.I!$AU$4,1,0) -> 1 | AU8: =+IF(P.I!AV8=P.I!$AV$4,1,0) -> 0 | AV8: =+IF(P.I!AW8=P.I!$AW$4,1,0) -> 1 | AW8: =+IF(P.I!AX8=P.I!$AX$4,1,0) -> 0 | AX8: =+IF(P.I!AY8=P.I!$AY$4,1,0) -> 0 | AY8: =+IF(P.I!AZ8=P.I!$AZ$4,1,0) -> 1 | AZ8: =+IF(P.I!BA8=P.I!$BA$4,1,0) -> 1 | BA8: =+IF(P.I!BB8=P.I!$BB$4,1,0) -> 0 | BB8: =+IF(P.I!BC8=P.I!$BC$4,1,0) -> 0 | BC8: =+IF(P.I!BD8=P.I!$BD$4,1,0) -> 0 | BD8: =+IF(P.I!BE8=P.I!$BE$4,1,0) -> 0 | BE8: =+IF(P.I!BF8=P.I!$BF$4,1,0) -> 0 | BF8: =+IF(P.I!BG8=P.I!$BG$4,1,0) -> 1 | BG8: =+IF(P.I!BH8=P.I!$BH$4,1,0) -> 0 | BH8: =+IF(P.I!BI8=P.I!$BI$4,1,0) -> 0 | BI8: =+IF(P.I!BJ8=P.I!$BJ$4,1,0) -> 0 | BJ8: =+IF(P.I!BK8=P.I!$BK$4,1,0) -> 0 | BK8: =+IF(P.I!BL8=P.I!$BL$4,1,0) -> 0 | BL8: =+IF(P.I!BM8=P.I!$BM$4,1,0) -> 0 | BM8: =+IF(P.I!BN8=P.I!$BN$4,1,0) -> 1 | BN8: =+IF(P.I!BO8=P.I!$BO$4,1,0) -> 0 | BO8: =+IF(P.I!BP8=P.I!$BP$4,1,0) -> 0 | BP8: =+IF(P.I!BQ8=P.I!$BQ$4,1,0) -> 0 | BQ8: =+IF(P.I!BR8=P.I!$BR$4,1,0) -> 0 | BR8: =+IF(P.I!BS8=P.I!$BS$4,1,0) -> 0 | BS8: =+IF(P.I!BT8=P.I!$BT$4,1,0) -> 0 | BT8: =+IF(P.I!BU8=P.I!$BU$4,1,0) -> 0 | BU8: =+IF(P.I!BV8=P.I!$BV$4,1,0) -> 0 | BV8: =+IF(P.I!BW8=P.I!$BW$4,1,0) -> 1 | BW8: =+IF(P.I!BX8=P.I!$BX$4,1,0) -> 0 | BX8: =+IF(P.I!BY8=P.I!$BY$4,1,0) -> 0 | BY8: =+IF(P.I!BZ8=P.I!$BZ$4,1,0) -> 0 | BZ8: =+IF(P.I!CA8=P.I!$CA$4,1,0) -> 0 | CA8: =+IF(P.I!CB8=P.I!$CB$4,1,0) -> 0 | CB8: =+IF(P.I!CC8=P.I!$CC$4,1,0) -> 1 | CC8: =+IF(P.I!CD8=P.I!$CD$4,1,0) -> 0 | CD8: =+IF(P.I!CE8=P.I!$CE$4,1,0) -> 0 | CE8: =+SUM(C8:AP8) -> 0 | CF8: =+CE8/$CF$3*100 -> 0 | CG8: =+CF8*5/100 -> 0 | CH8: =+SUM(AQ8:CD8) -> 9 | CI8: =+CH8/$CI$3*100 -> 23.684211 | CJ8: =+CI8*5/100 -> 1.1842105 | CK8: =+CE8+CH8 -> 9 | CL8: =+CK8/$CL$3*100 -> 11.688312 | CM8: =+CL8*5/100 -> 0.58441558
A9: 5 | B9: =P.I!#REF! -> #REF! | C9: =+IF(P.I!D8=P.I!$D$4,1,0) -> 0 | D9: =+IF(P.I!E8=P.I!$E$4,1,0) -> 0 | E9: =+IF(P.I!F8=P.I!$F$4,1,0) -> 0 | F9: =+IF(P.I!G8=P.I!$G$4,1,0) -> 0 | G9: =+IF(P.I!H8=P.I!$H$4,1,0) -> 0 | H9: =+IF(P.I!I8=P.I!$I$4,1,0) -> 0 | I9: =+IF(P.I!J8=P.I!$J$4,1,0) -> 0 | J9: =+IF(P.I!K8=P.I!$K$4,1,0) -> 0 | K9: =+IF(P.I!L8=P.I!$L$4,1,0) -> 0 | L9: =+IF(P.I!M8=P.I!$M$4,1,0) -> 0 | M9: =+IF(P.I!N8=P.I!$N$4,1,0) -> 0 | N9: =+IF(P.I!O8=P.I!$O$4,1,0) -> 0 | O9: =+IF(P.I!P8=P.I!$P$4,1,0) -> 0 | P9: =+IF(P.I!Q8=P.I!$Q$4,1,0) -> 0 | Q9: =+IF(P.I!R8=P.I!$R$4,1,0) -> 0 | R9: =+IF(P.I!S8=P.I!$S$4,1,0) -> 0 | S9: =+IF(P.I!T8=P.I!$T$4,1,0) -> 0 | T9: =+IF(P.I!U8=P.I!$U$4,1,0) -> 0 | U9: =+IF(P.I!V8=P.I!$V$4,1,0) -> 0 | V9: =+IF(P.I!W8=P.I!$W$4,1,0) -> 0 | W9: =+IF(P.I!X8=P.I!$X$4,1,0) -> 0 | X9: =+IF(P.I!Y8=P.I!$Y$4,1,0) -> 0 | Y9: =+IF(P.I!Z8=P.I!$Z$4,1,0) -> 0 | Z9: =+IF(P.I!AA8=P.I!$AA$4,1,0) -> 0 | AA9: =+IF(P.I!AB8=P.I!$AB$4,1,0) -> 0 | AB9: =+IF(P.I!AC8=P.I!$AC$4,1,0) -> 0 | AC9: =+IF(P.I!AD8=P.I!$AD$4,1,0) -> 0 | AD9: =+IF(P.I!AE8=P.I!$AE$4,1,0) -> 0 | AE9: =+IF(P.I!AF8=P.I!$AF$4,1,0) -> 0 | AF9: =+IF(P.I!AG8=P.I!$AG$4,1,0) -> 0 | AG9: =+IF(P.I!AH8=P.I!$AH$4,1,0) -> 0 | AH9: =+IF(P.I!AI8=P.I!$AI$4,1,0) -> 0 | AI9: =+IF(P.I!AJ8=P.I!$AJ$4,1,0) -> 0 | AJ9: =+IF(P.I!AK8=P.I!$AK$4,1,0) -> 0 | AK9: =+IF(P.I!AL8=P.I!$AL$4,1,0) -> 0 | AL9: =+IF(P.I!AM8=P.I!$AM$4,1,0) -> 0 | AM9: =+IF(P.I!AN8=P.I!$AN$4,1,0) -> 0 | AN9: =+IF(P.I!AO8=P.I!$AO$4,1,0) -> 0 | AO9: =+IF(P.I!AP8=P.I!$AP$4,1,0) -> 0 | AP9: =+IF(P.I!AQ9=P.I!$AQ$4,1,0) -> 0 | AQ9: =+IF(P.I!AR9=P.I!$AR$4,1,0) -> 1 | AR9: =+IF(P.I!AS9=P.I!$AS$4,1,0) -> 1 | AS9: =+IF(P.I!AT9=P.I!$AT$4,1,0) -> 0 | AT9: =+IF(P.I!AU9=P.I!$AU$4,1,0) -> 1 | AU9: =+IF(P.I!AV9=P.I!$AV$4,1,0) -> 0 | AV9: =+IF(P.I!AW9=P.I!$AW$4,1,0) -> 0 | AW9: =+IF(P.I!AX9=P.I!$AX$4,1,0) -> 0 | AX9: =+IF(P.I!AY9=P.I!$AY$4,1,0) -> 0 | AY9: =+IF(P.I!AZ9=P.I!$AZ$4,1,0) -> 1 | AZ9: =+IF(P.I!BA9=P.I!$BA$4,1,0) -> 0 | BA9: =+IF(P.I!BB9=P.I!$BB$4,1,0) -> 0 | BB9: =+IF(P.I!BC9=P.I!$BC$4,1,0) -> 0 | BC9: =+IF(P.I!BD9=P.I!$BD$4,1,0) -> 0 | BD9: =+IF(P.I!BE9=P.I!$BE$4,1,0) -> 0 | BE9: =+IF(P.I!BF9=P.I!$BF$4,1,0) -> 0 | BF9: =+IF(P.I!BG9=P.I!$BG$4,1,0) -> 0 | BG9: =+IF(P.I!BH9=P.I!$BH$4,1,0) -> 0 | BH9: =+IF(P.I!BI9=P.I!$BI$4,1,0) -> 0 | BI9: =+IF(P.I!BJ9=P.I!$BJ$4,1,0) -> 0 | BJ9: =+IF(P.I!BK9=P.I!$BK$4,1,0) -> 0 | BK9: =+IF(P.I!BL9=P.I!$BL$4,1,0) -> 0 | BL9: =+IF(P.I!BM9=P.I!$BM$4,1,0) -> 0 | BM9: =+IF(P.I!BN9=P.I!$BN$4,1,0) -> 0 | BN9: =+IF(P.I!BO9=P.I!$BO$4,1,0) -> 0 | BO9: =+IF(P.I!BP9=P.I!$BP$4,1,0) -> 1 | BP9: =+IF(P.I!BQ9=P.I!$BQ$4,1,0) -> 0 | BQ9: =+IF(P.I!BR9=P.I!$BR$4,1,0) -> 0 | BR9: =+IF(P.I!BS9=P.I!$BS$4,1,0) -> 1 | BS9: =+IF(P.I!BT9=P.I!$BT$4,1,0) -> 0 | BT9: =+IF(P.I!BU9=P.I!$BU$4,1,0) -> 1 | BU9: =+IF(P.I!BV9=P.I!$BV$4,1,0) -> 0 | BV9: =+IF(P.I!BW9=P.I!$BW$4,1,0) -> 1 | BW9: =+IF(P.I!BX9=P.I!$BX$4,1,0) -> 0 | BX9: =+IF(P.I!BY9=P.I!$BY$4,1,0) -> 0 | BY9: =+IF(P.I!BZ9=P.I!$BZ$4,1,0) -> 0 | BZ9: =+IF(P.I!CA9=P.I!$CA$4,1,0) -> 0 | CA9: =+IF(P.I!CB9=P.I!$CB$4,1,0) -> 1 | CB9: =+IF(P.I!CC9=P.I!$CC$4,1,0) -> 0 | CC9: =+IF(P.I!CD9=P.I!$CD$4,1,0) -> 0 | CD9: =+IF(P.I!CE9=P.I!$CE$4,1,0) -> 0 | CE9: =+SUM(C9:AP9) -> 0 | CF9: =+CE9/$CF$3*100 -> 0 | CG9: =+CF9*5/100 -> 0 | CH9: =+SUM(AQ9:CD9) -> 9 | CI9: =+CH9/$CI$3*100 -> 23.684211 | CJ9: =+CI9*5/100 -> 1.1842105 | CK9: =+CE9+CH9 -> 9 | CL9: =+CK9/$CL$3*100 -> 11.688312 | CM9: =+CL9*5/100 -> 0.58441558
A10: 6 | B10: =P.I!C9 -> ANDRÉS DAVID OSUNA ALVAREZ | C10: =+IF(P.I!D11=P.I!$D$4,1,0) -> 0 | D10: =+IF(P.I!E11=P.I!$E$4,1,0) -> 0 | E10: =+IF(P.I!F11=P.I!$F$4,1,0) -> 0 | F10: =+IF(P.I!G11=P.I!$G$4,1,0) -> 0 | G10: =+IF(P.I!H11=P.I!$H$4,1,0) -> 0 | H10: =+IF(P.I!I11=P.I!$I$4,1,0) -> 0 | I10: =+IF(P.I!J11=P.I!$J$4,1,0) -> 0 | J10: =+IF(P.I!K11=P.I!$K$4,1,0) -> 0 | K10: =+IF(P.I!L11=P.I!$L$4,1,0) -> 0 | L10: =+IF(P.I!M11=P.I!$M$4,1,0) -> 0 | M10: =+IF(P.I!N11=P.I!$N$4,1,0) -> 0 | N10: =+IF(P.I!O11=P.I!$O$4,1,0) -> 0 | O10: =+IF(P.I!P11=P.I!$P$4,1,0) -> 0 | P10: =+IF(P.I!Q11=P.I!$Q$4,1,0) -> 0 | Q10: =+IF(P.I!R11=P.I!$R$4,1,0) -> 0 | R10: =+IF(P.I!S11=P.I!$S$4,1,0) -> 0 | S10: =+IF(P.I!T11=P.I!$T$4,1,0) -> 0 | T10: =+IF(P.I!U11=P.I!$U$4,1,0) -> 0 | U10: =+IF(P.I!V11=P.I!$V$4,1,0) -> 0 | V10: =+IF(P.I!W11=P.I!$W$4,1,0) -> 0 | W10: =+IF(P.I!X11=P.I!$X$4,1,0) -> 0 | X10: =+IF(P.I!Y11=P.I!$Y$4,1,0) -> 0 | Y10: =+IF(P.I!Z11=P.I!$Z$4,1,0) -> 0 | Z10: =+IF(P.I!AA11=P.I!$AA$4,1,0) -> 0 | AA10: =+IF(P.I!AB11=P.I!$AB$4,1,0) -> 0 | AB10: =+IF(P.I!AC11=P.I!$AC$4,1,0) -> 0 | AC10: =+IF(P.I!AD11=P.I!$AD$4,1,0) -> 0 | AD10: =+IF(P.I!AE11=P.I!$AE$4,1,0) -> 0 | AE10: =+IF(P.I!AF11=P.I!$AF$4,1,0) -> 0 | AF10: =+IF(P.I!AG11=P.I!$AG$4,1,0) -> 0 | AG10: =+IF(P.I!AH11=P.I!$AH$4,1,0) -> 0 | AH10: =+IF(P.I!AI11=P.I!$AI$4,1,0) -> 0 | AI10: =+IF(P.I!AJ11=P.I!$AJ$4,1,0) -> 0 | AJ10: =+IF(P.I!AK11=P.I!$AK$4,1,0) -> 0 | AK10: =+IF(P.I!AL11=P.I!$AL$4,1,0) -> 0 | AL10: =+IF(P.I!AM11=P.I!$AM$4,1,0) -> 0 | AM10: =+IF(P.I!AN11=P.I!$AN$4,1,0) -> 0 | AN10: =+IF(P.I!AO11=P.I!$AO$4,1,0) -> 0 | AO10: =+IF(P.I!AP11=P.I!$AP$4,1,0) -> 0 | AP10: =+IF(P.I!AQ11=P.I!$AQ$4,1,0) -> 0 | AQ10: =+IF(P.I!AR11=P.I!$AR$4,1,0) -> 1 | AR10: =+IF(P.I!AS11=P.I!$AS$4,1,0) -> 0 | AS10: =+IF(P.I!AT11=P.I!$AT$4,1,0) -> 0 | AT10: =+IF(P.I!AU11=P.I!$AU$4,1,0) -> 0 | AU10: =+IF(P.I!AV11=P.I!$AV$4,1,0) -> 0 | AV10: =+IF(P.I!AW11=P.I!$AW$4,1,0) -> 1 | AW10: =+IF(P.I!AX11=P.I!$AX$4,1,0) -> 0 | AX10: =+IF(P.I!AY11=P.I!$AY$4,1,0) -> 0 | AY10: =+IF(P.I!AZ11=P.I!$AZ$4,1,0) -> 0 | AZ10: =+IF(P.I!BA11=P.I!$BA$4,1,0) -> 0 | BA10: =+IF(P.I!BB11=P.I!$BB$4,1,0) -> 0 | BB10: =+IF(P.I!BC11=P.I!$BC$4,1,0) -> 0 | BC10: =+IF(P.I!BD11=P.I!$BD$4,1,0) -> 1 | BD10: =+IF(P.I!BE11=P.I!$BE$4,1,0) -> 0 | BE10: =+IF(P.I!BF11=P.I!$BF$4,1,0) -> 1 | BF10: =+IF(P.I!BG11=P.I!$BG$4,1,0) -> 0 | BG10: =+IF(P.I!BH11=P.I!$BH$4,1,0) -> 0 | BH10: =+IF(P.I!BI11=P.I!$BI$4,1,0) -> 0 | BI10: =+IF(P.I!BJ11=P.I!$BJ$4,1,0) -> 1 | BJ10: =+IF(P.I!BK11=P.I!$BK$4,1,0) -> 0 | BK10: =+IF(P.I!BL11=P.I!$BL$4,1,0) -> 0 | BL10: =+IF(P.I!BM11=P.I!$BM$4,1,0) -> 0 | BM10: =+IF(P.I!BN11=P.I!$BN$4,1,0) -> 0 | BN10: =+IF(P.I!BO11=P.I!$BO$4,1,0) -> 0 | BO10: =+IF(P.I!BP11=P.I!$BP$4,1,0) -> 1 | BP10: =+IF(P.I!BQ11=P.I!$BQ$4,1,0) -> 0 | BQ10: =+IF(P.I!BR11=P.I!$BR$4,1,0) -> 0 | BR10: =+IF(P.I!BS11=P.I!$BS$4,1,0) -> 1 | BS10: =+IF(P.I!BT11=P.I!$BT$4,1,0) -> 0 | BT10: =+IF(P.I!BU11=P.I!$BU$4,1,0) -> 0 | BU10: =+IF(P.I!BV11=P.I!$BV$4,1,0) -> 0 | BV10: =+IF(P.I!BW11=P.I!$BW$4,1,0) -> 0 | BW10: =+IF(P.I!BX11=P.I!$BX$4,1,0) -> 0 | BX10: =+IF(P.I!BY11=P.I!$BY$4,1,0) -> 1 | BY10: =+IF(P.I!BZ11=P.I!$BZ$4,1,0) -> 0 | BZ10: =+IF(P.I!CA11=P.I!$CA$4,1,0) -> 0 | CA10: =+IF(P.I!CB11=P.I!$CB$4,1,0) -> 0 | CB10: =+IF(P.I!CC11=P.I!$CC$4,1,0) -> 1 | CC10: =+IF(P.I!CD11=P.I!$CD$4,1,0) -> 0 | CD10: =+IF(P.I!CE11=P.I!$CE$4,1,0) -> 0 | CE10: =+SUM(C10:AP10) -> 0 | CF10: =+CE10/$CF$3*100 -> 0 | CG10: =+CF10*5/100 -> 0 | CH10: =+SUM(AQ10:CD10) -> 9 | CI10: =+CH10/$CI$3*100 -> 23.684211 | CJ10: =+CI10*5/100 -> 1.1842105 | CK10: =+CE10+CH10 -> 9 | CL10: =+CK10/$CL$3*100 -> 11.688312 | CM10: =+CL10*5/100 -> 0.58441558
A11: 7 | B11: =P.I!#REF! -> #REF! | C11: =+IF(P.I!D12=P.I!$D$4,1,0) -> 0 | D11: =+IF(P.I!E12=P.I!$E$4,1,0) -> 0 | E11: =+IF(P.I!F12=P.I!$F$4,1,0) -> 0 | F11: =+IF(P.I!G12=P.I!$G$4,1,0) -> 0 | G11: =+IF(P.I!H12=P.I!$H$4,1,0) -> 0 | H11: =+IF(P.I!I12=P.I!$I$4,1,0) -> 0 | I11: =+IF(P.I!J12=P.I!$J$4,1,0) -> 0 | J11: =+IF(P.I!K12=P.I!$K$4,1,0) -> 0 | K11: =+IF(P.I!L12=P.I!$L$4,1,0) -> 0 | L11: =+IF(P.I!M12=P.I!$M$4,1,0) -> 0 | M11: =+IF(P.I!N12=P.I!$N$4,1,0) -> 0 | N11: =+IF(P.I!O12=P.I!$O$4,1,0) -> 0 | O11: =+IF(P.I!P12=P.I!$P$4,1,0) -> 0 | P11: =+IF(P.I!Q12=P.I!$Q$4,1,0) -> 0 | Q11: =+IF(P.I!R12=P.I!$R$4,1,0) -> 0 | R11: =+IF(P.I!S12=P.I!$S$4,1,0) -> 0 | S11: =+IF(P.I!T12=P.I!$T$4,1,0) -> 0 | T11: =+IF(P.I!U12=P.I!$U$4,1,0) -> 0 | U11: =+IF(P.I!V12=P.I!$V$4,1,0) -> 0 | V11: =+IF(P.I!W12=P.I!$W$4,1,0) -> 0 | W11: =+IF(P.I!X12=P.I!$X$4,1,0) -> 0 | X11: =+IF(P.I!Y12=P.I!$Y$4,1,0) -> 0 | Y11: =+IF(P.I!Z12=P.I!$Z$4,1,0) -> 0 | Z11: =+IF(P.I!AA12=P.I!$AA$4,1,0) -> 0 | AA11: =+IF(P.I!AB12=P.I!$AB$4,1,0) -> 0 | AB11: =+IF(P.I!AC12=P.I!$AC$4,1,0) -> 0 | AC11: =+IF(P.I!AD12=P.I!$AD$4,1,0) -> 0 | AD11: =+IF(P.I!AE12=P.I!$AE$4,1,0) -> 0 | AE11: =+IF(P.I!AF12=P.I!$AF$4,1,0) -> 0 | AF11: =+IF(P.I!AG12=P.I!$AG$4,1,0) -> 0 | AG11: =+IF(P.I!AH12=P.I!$AH$4,1,0) -> 0 | AH11: =+IF(P.I!AI12=P.I!$AI$4,1,0) -> 0 | AI11: =+IF(P.I!AJ12=P.I!$AJ$4,1,0) -> 0 | AJ11: =+IF(P.I!AK12=P.I!$AK$4,1,0) -> 0 | AK11: =+IF(P.I!AL12=P.I!$AL$4,1,0) -> 0 | AL11: =+IF(P.I!AM12=P.I!$AM$4,1,0) -> 0 | AM11: =+IF(P.I!AN12=P.I!$AN$4,1,0) -> 0 | AN11: =+IF(P.I!AO12=P.I!$AO$4,1,0) -> 0 | AO11: =+IF(P.I!AP12=P.I!$AP$4,1,0) -> 0 | AP11: =+IF(P.I!AQ12=P.I!$AQ$4,1,0) -> 0 | AQ11: =+IF(P.I!AR12=P.I!$AR$4,1,0) -> 1 | AR11: =+IF(P.I!AS12=P.I!$AS$4,1,0) -> 0 | AS11: =+IF(P.I!AT12=P.I!$AT$4,1,0) -> 0 | AT11: =+IF(P.I!AU12=P.I!$AU$4,1,0) -> 0 | AU11: =+IF(P.I!AV12=P.I!$AV$4,1,0) -> 0 | AV11: =+IF(P.I!AW12=P.I!$AW$4,1,0) -> 1 | AW11: =+IF(P.I!AX12=P.I!$AX$4,1,0) -> 0 | AX11: =+IF(P.I!AY12=P.I!$AY$4,1,0) -> 1 | AY11: =+IF(P.I!AZ12=P.I!$AZ$4,1,0) -> 0 | AZ11: =+IF(P.I!BA12=P.I!$BA$4,1,0) -> 0 | BA11: =+IF(P.I!BB12=P.I!$BB$4,1,0) -> 0 | BB11: =+IF(P.I!BC12=P.I!$BC$4,1,0) -> 0 | BC11: =+IF(P.I!BD12=P.I!$BD$4,1,0) -> 1 | BD11: =+IF(P.I!BE12=P.I!$BE$4,1,0) -> 0 | BE11: =+IF(P.I!BF12=P.I!$BF$4,1,0) -> 0 | BF11: =+IF(P.I!BG12=P.I!$BG$4,1,0) -> 0 | BG11: =+IF(P.I!BH12=P.I!$BH$4,1,0) -> 1 | BH11: =+IF(P.I!BI12=P.I!$BI$4,1,0) -> 1 | BI11: =+IF(P.I!BJ12=P.I!$BJ$4,1,0) -> 0 | BJ11: =+IF(P.I!BK12=P.I!$BK$4,1,0) -> 1 | BK11: =+IF(P.I!BL12=P.I!$BL$4,1,0) -> 1 | BL11: =+IF(P.I!BM12=P.I!$BM$4,1,0) -> 0 | BM11: =+IF(P.I!BN12=P.I!$BN$4,1,0) -> 0 | BN11: =+IF(P.I!BO12=P.I!$BO$4,1,0) -> 0 | BO11: =+IF(P.I!BP12=P.I!$BP$4,1,0) -> 0 | BP11: =+IF(P.I!BQ12=P.I!$BQ$4,1,0) -> 0 | BQ11: =+IF(P.I!BR12=P.I!$BR$4,1,0) -> 0 | BR11: =+IF(P.I!BS12=P.I!$BS$4,1,0) -> 0 | BS11: =+IF(P.I!BT12=P.I!$BT$4,1,0) -> 0 | BT11: =+IF(P.I!BU12=P.I!$BU$4,1,0) -> 0 | BU11: =+IF(P.I!BV12=P.I!$BV$4,1,0) -> 1 | BV11: =+IF(P.I!BW12=P.I!$BW$4,1,0) -> 0 | BW11: =+IF(P.I!BX12=P.I!$BX$4,1,0) -> 1 | BX11: =+IF(P.I!BY12=P.I!$BY$4,1,0) -> 1 | BY11: =+IF(P.I!BZ12=P.I!$BZ$4,1,0) -> 1 | BZ11: =+IF(P.I!CA12=P.I!$CA$4,1,0) -> 0 | CA11: =+IF(P.I!CB12=P.I!$CB$4,1,0) -> 0 | CB11: =+IF(P.I!CC12=P.I!$CC$4,1,0) -> 1 | CC11: =+IF(P.I!CD12=P.I!$CD$4,1,0) -> 0 | CD11: =+IF(P.I!CE12=P.I!$CE$4,1,0) -> 0 | CE11: =+SUM(C11:AP11) -> 0 | CF11: =+CE11/$CF$3*100 -> 0 | CG11: =+CF11*5/100 -> 0 | CH11: =+SUM(AQ11:CD11) -> 13 | CI11: =+CH11/$CI$3*100 -> 34.210526 | CJ11: =+CI11*5/100 -> 1.7105263 | CK11: =+CE11+CH11 -> 13 | CL11: =+CK11/$CL$3*100 -> 16.883117 | CM11: =+CL11*5/100 -> 0.84415584
A12: 8 | B12: =P.I!C13 -> CELENY LUZ ACOSTA MONTERROSA | C12: =+IF(P.I!D13=P.I!$D$4,1,0) -> 0 | D12: =+IF(P.I!E13=P.I!$E$4,1,0) -> 0 | E12: =+IF(P.I!F13=P.I!$F$4,1,0) -> 0 | F12: =+IF(P.I!G13=P.I!$G$4,1,0) -> 0 | G12: =+IF(P.I!H13=P.I!$H$4,1,0) -> 0 | H12: =+IF(P.I!I13=P.I!$I$4,1,0) -> 0 | I12: =+IF(P.I!J13=P.I!$J$4,1,0) -> 0 | J12: =+IF(P.I!K13=P.I!$K$4,1,0) -> 0 | K12: =+IF(P.I!L13=P.I!$L$4,1,0) -> 0 | L12: =+IF(P.I!M13=P.I!$M$4,1,0) -> 0 | M12: =+IF(P.I!N13=P.I!$N$4,1,0) -> 0 | N12: =+IF(P.I!O13=P.I!$O$4,1,0) -> 0 | O12: =+IF(P.I!P13=P.I!$P$4,1,0) -> 0 | P12: =+IF(P.I!Q13=P.I!$Q$4,1,0) -> 0 | Q12: =+IF(P.I!R13=P.I!$R$4,1,0) -> 0 | R12: =+IF(P.I!S13=P.I!$S$4,1,0) -> 0 | S12: =+IF(P.I!T13=P.I!$T$4,1,0) -> 0 | T12: =+IF(P.I!U13=P.I!$U$4,1,0) -> 0 | U12: =+IF(P.I!V13=P.I!$V$4,1,0) -> 0 | V12: =+IF(P.I!W13=P.I!$W$4,1,0) -> 0 | W12: =+IF(P.I!X13=P.I!$X$4,1,0) -> 0 | X12: =+IF(P.I!Y13=P.I!$Y$4,1,0) -> 0 | Y12: =+IF(P.I!Z13=P.I!$Z$4,1,0) -> 0 | Z12: =+IF(P.I!AA13=P.I!$AA$4,1,0) -> 0 | AA12: =+IF(P.I!AB13=P.I!$AB$4,1,0) -> 0 | AB12: =+IF(P.I!AC13=P.I!$AC$4,1,0) -> 0 | AC12: =+IF(P.I!AD13=P.I!$AD$4,1,0) -> 0 | AD12: =+IF(P.I!AE13=P.I!$AE$4,1,0) -> 0 | AE12: =+IF(P.I!AF13=P.I!$AF$4,1,0) -> 0 | AF12: =+IF(P.I!AG13=P.I!$AG$4,1,0) -> 0 | AG12: =+IF(P.I!AH13=P.I!$AH$4,1,0) -> 0 | AH12: =+IF(P.I!AI13=P.I!$AI$4,1,0) -> 0 | AI12: =+IF(P.I!AJ13=P.I!$AJ$4,1,0) -> 0 | AJ12: =+IF(P.I!AK13=P.I!$AK$4,1,0) -> 0 | AK12: =+IF(P.I!AL13=P.I!$AL$4,1,0) -> 0 | AL12: =+IF(P.I!AM13=P.I!$AM$4,1,0) -> 0 | AM12: =+IF(P.I!AN13=P.I!$AN$4,1,0) -> 0 | AN12: =+IF(P.I!AO13=P.I!$AO$4,1,0) -> 0 | AO12: =+IF(P.I!AP13=P.I!$AP$4,1,0) -> 0 | AP12: =+IF(P.I!AQ13=P.I!$AQ$4,1,0) -> 0 | AQ12: =+IF(P.I!AR41=P.I!$AR$4,1,0) -> 1 | AR12: =+IF(P.I!AS41=P.I!$AS$4,1,0) -> 0 | AS12: =+IF(P.I!AT41=P.I!$AT$4,1,0) -> 1 | AT12: =+IF(P.I!AU41=P.I!$AU$4,1,0) -> 0 | AU12: =+IF(P.I!AV41=P.I!$AV$4,1,0) -> 0 | AV12: =+IF(P.I!AW41=P.I!$AW$4,1,0) -> 1 | AW12: =+IF(P.I!AX41=P.I!$AX$4,1,0) -> 1 | AX12: =+IF(P.I!AY41=P.I!$AY$4,1,0) -> 0 | AY12: =+IF(P.I!AZ41=P.I!$AZ$4,1,0) -> 0 | AZ12: =+IF(P.I!BA41=P.I!$BA$4,1,0) -> 0 | BA12: =+IF(P.I!BB41=P.I!$BB$4,1,0) -> 0 | BB12: =+IF(P.I!BC41=P.I!$BC$4,1,0) -> 0 | BC12: =+IF(P.I!BD41=P.I!$BD$4,1,0) -> 1 | BD12: =+IF(P.I!BE41=P.I!$BE$4,1,0) -> 0 | BE12: =+IF(P.I!BF41=P.I!$BF$4,1,0) -> 0 | BF12: =+IF(P.I!BG41=P.I!$BG$4,1,0) -> 0 | BG12: =+IF(P.I!BH41=P.I!$BH$4,1,0) -> 0 | BH12: =+IF(P.I!BI41=P.I!$BI$4,1,0) -> 1 | BI12: =+IF(P.I!BJ41=P.I!$BJ$4,1,0) -> 0 | BJ12: =+IF(P.I!BK41=P.I!$BK$4,1,0) -> 0 | BK12: =+IF(P.I!BL41=P.I!$BL$4,1,0) -> 0 | BL12: =+IF(P.I!BM41=P.I!$BM$4,1,0) -> 0 | BM12: =+IF(P.I!BN41=P.I!$BN$4,1,0) -> 0 | BN12: =+IF(P.I!BO41=P.I!$BO$4,1,0) -> 0 | BO12: =+IF(P.I!BP41=P.I!$BP$4,1,0) -> 0 | BP12: =+IF(P.I!BQ41=P.I!$BQ$4,1,0) -> 0 | BQ12: =+IF(P.I!BR41=P.I!$BR$4,1,0) -> 0 | BR12: =+IF(P.I!BS41=P.I!$BS$4,1,0) -> 0 | BS12: =+IF(P.I!BT41=P.I!$BT$4,1,0) -> 0 | BT12: =+IF(P.I!BU41=P.I!$BU$4,1,0) -> 0 | BU12: =+IF(P.I!BV41=P.I!$BV$4,1,0) -> 1 | BV12: =+IF(P.I!BW41=P.I!$BW$4,1,0) -> 0 | BW12: =+IF(P.I!BX41=P.I!$BX$4,1,0) -> 0 | BX12: =+IF(P.I!BY41=P.I!$BY$4,1,0) -> 1 | BY12: =+IF(P.I!BZ41=P.I!$BZ$4,1,0) -> 1 | BZ12: =+IF(P.I!CA41=P.I!$CA$4,1,0) -> 0 | CA12: =+IF(P.I!CB41=P.I!$CB$4,1,0) -> 1 | CB12: =+IF(P.I!CC41=P.I!$CC$4,1,0) -> 1 | CC12: =+IF(P.I!CD13=P.I!$CD$4,1,0) -> 0 | CD12: =+IF(P.I!CE13=P.I!$CE$4,1,0) -> 0 | CE12: =+SUM(C12:AP12) -> 0 | CF12: =+CE12/$CF$3*100 -> 0 | CG12: =+CF12*5/100 -> 0 | CH12: =+SUM(AQ12:CD12) -> 11 | CI12: =+CH12/$CI$3*100 -> 28.947368 | CJ12: =+CI12*5/100 -> 1.4473684 | CK12: =+CE12+CH12 -> 11 | CL12: =+CK12/$CL$3*100 -> 14.285714 | CM12: =+CL12*5/100 -> 0.71428571
A13: 9 | B13: =P.I!C16 -> DEIVER DAVID FLORES LOPEZ | C13: =+IF(P.I!D16=P.I!$D$4,1,0) -> 0 | D13: =+IF(P.I!E16=P.I!$E$4,1,0) -> 0 | E13: =+IF(P.I!F16=P.I!$F$4,1,0) -> 0 | F13: =+IF(P.I!G16=P.I!$G$4,1,0) -> 0 | G13: =+IF(P.I!H16=P.I!$H$4,1,0) -> 0 | H13: =+IF(P.I!I16=P.I!$I$4,1,0) -> 0 | I13: =+IF(P.I!J16=P.I!$J$4,1,0) -> 0 | J13: =+IF(P.I!K16=P.I!$K$4,1,0) -> 0 | K13: =+IF(P.I!L16=P.I!$L$4,1,0) -> 0 | L13: =+IF(P.I!M16=P.I!$M$4,1,0) -> 0 | M13: =+IF(P.I!N16=P.I!$N$4,1,0) -> 0 | N13: =+IF(P.I!O16=P.I!$O$4,1,0) -> 0 | O13: =+IF(P.I!P16=P.I!$P$4,1,0) -> 0 | P13: =+IF(P.I!Q16=P.I!$Q$4,1,0) -> 0 | Q13: =+IF(P.I!R16=P.I!$R$4,1,0) -> 0 | R13: =+IF(P.I!S16=P.I!$S$4,1,0) -> 0 | S13: =+IF(P.I!T16=P.I!$T$4,1,0) -> 0 | T13: =+IF(P.I!U16=P.I!$U$4,1,0) -> 0 | U13: =+IF(P.I!V16=P.I!$V$4,1,0) -> 0 | V13: =+IF(P.I!W16=P.I!$W$4,1,0) -> 0 | W13: =+IF(P.I!X16=P.I!$X$4,1,0) -> 0 | X13: =+IF(P.I!Y16=P.I!$Y$4,1,0) -> 0 | Y13: =+IF(P.I!Z16=P.I!$Z$4,1,0) -> 0 | Z13: =+IF(P.I!AA16=P.I!$AA$4,1,0) -> 0 | AA13: =+IF(P.I!AB16=P.I!$AB$4,1,0) -> 0 | AB13: =+IF(P.I!AC16=P.I!$AC$4,1,0) -> 0 | AC13: =+IF(P.I!AD16=P.I!$AD$4,1,0) -> 0 | AD13: =+IF(P.I!AE16=P.I!$AE$4,1,0) -> 0 | AE13: =+IF(P.I!AF16=P.I!$AF$4,1,0) -> 0 | AF13: =+IF(P.I!AG16=P.I!$AG$4,1,0) -> 0 | AG13: =+IF(P.I!AH16=P.I!$AH$4,1,0) -> 0 | AH13: =+IF(P.I!AI16=P.I!$AI$4,1,0) -> 0 | AI13: =+IF(P.I!AJ16=P.I!$AJ$4,1,0) -> 0 | AJ13: =+IF(P.I!AK16=P.I!$AK$4,1,0) -> 0 | AK13: =+IF(P.I!AL16=P.I!$AL$4,1,0) -> 0 | AL13: =+IF(P.I!AM16=P.I!$AM$4,1,0) -> 0 | AM13: =+IF(P.I!AN16=P.I!$AN$4,1,0) -> 0 | AN13: =+IF(P.I!AO16=P.I!$AO$4,1,0) -> 0 | AO13: =+IF(P.I!AP16=P.I!$AP$4,1,0) -> 0 | AP13: =+IF(P.I!AQ16=P.I!$AQ$4,1,0) -> 0 | AQ13: =+IF(P.I!AR16=P.I!$AR$4,1,0) -> 0 | AR13: =+IF(P.I!AS16=P.I!$AS$4,1,0) -> 0 | AS13: =+IF(P.I!AT16=P.I!$AT$4,1,0) -> 0 | AT13: =+IF(P.I!AU16=P.I!$AU$4,1,0) -> 0 | AU13: =+IF(P.I!AV16=P.I!$AV$4,1,0) -> 0 | AV13: =+IF(P.I!AW16=P.I!$AW$4,1,0) -> 0 | AW13: =+IF(P.I!AX16=P.I!$AX$4,1,0) -> 1 | AX13: =+IF(P.I!AY16=P.I!$AY$4,1,0) -> 0 | AY13: =+IF(P.I!AZ16=P.I!$AZ$4,1,0) -> 1 | AZ13: =+IF(P.I!BA16=P.I!$BA$4,1,0) -> 0 | BA13: =+IF(P.I!BB16=P.I!$BB$4,1,0) -> 1 | BB13: =+IF(P.I!BC16=P.I!$BC$4,1,0) -> 0 | BC13: =+IF(P.I!BD16=P.I!$BD$4,1,0) -> 1 | BD13: =+IF(P.I!BE16=P.I!$BE$4,1,0) -> 1 | BE13: =+IF(P.I!BF16=P.I!$BF$4,1,0) -> 1 | BF13: =+IF(P.I!BG16=P.I!$BG$4,1,0) -> 0 | BG13: =+IF(P.I!BH16=P.I!$BH$4,1,0) -> 1 | BH13: =+IF(P.I!BI16=P.I!$BI$4,1,0) -> 0 | BI13: =+IF(P.I!BJ16=P.I!$BJ$4,1,0) -> 0 | BJ13: =+IF(P.I!BK16=P.I!$BK$4,1,0) -> 0 | BK13: =+IF(P.I!BL16=P.I!$BL$4,1,0) -> 0 | BL13: =+IF(P.I!BM16=P.I!$BM$4,1,0) -> 1 | BM13: =+IF(P.I!BN16=P.I!$BN$4,1,0) -> 0 | BN13: =+IF(P.I!BO16=P.I!$BO$4,1,0) -> 0 | BO13: =+IF(P.I!BP16=P.I!$BP$4,1,0) -> 0 | BP13: =+IF(P.I!BQ16=P.I!$BQ$4,1,0) -> 0 | BQ13: =+IF(P.I!BR16=P.I!$BR$4,1,0) -> 0 | BR13: =+IF(P.I!BS16=P.I!$BS$4,1,0) -> 0 | BS13: =+IF(P.I!BT16=P.I!$BT$4,1,0) -> 0 | BT13: =+IF(P.I!BU16=P.I!$BU$4,1,0) -> 0 | BU13: =+IF(P.I!BV16=P.I!$BV$4,1,0) -> 1 | BV13: =+IF(P.I!BW16=P.I!$BW$4,1,0) -> 0 | BW13: =+IF(P.I!BX16=P.I!$BX$4,1,0) -> 0 | BX13: =+IF(P.I!BY16=P.I!$BY$4,1,0) -> 1 | BY13: =+IF(P.I!BZ16=P.I!$BZ$4,1,0) -> 1 | BZ13: =+IF(P.I!CA16=P.I!$CA$4,1,0) -> 0 | CA13: =+IF(P.I!CB16=P.I!$CB$4,1,0) -> 0 | CB13: =+IF(P.I!CC16=P.I!$CC$4,1,0) -> 0 | CC13: =+IF(P.I!CD16=P.I!$CD$4,1,0) -> 0 | CD13: =+IF(P.I!CE16=P.I!$CE$4,1,0) -> 0 | CE13: =+SUM(C13:AP13) -> 0 | CF13: =+CE13/$CF$3*100 -> 0 | CG13: =+CF13*5/100 -> 0 | CH13: =+SUM(AQ13:CD13) -> 11 | CI13: =+CH13/$CI$3*100 -> 28.947368 | CJ13: =+CI13*5/100 -> 1.4473684 | CK13: =+CE13+CH13 -> 11 | CL13: =+CK13/$CL$3*100 -> 14.285714 | CM13: =+CL13*5/100 -> 0.71428571
A14: 10 | B14: =P.I!#REF! -> #REF! | C14: =+IF(P.I!#REF!=P.I!$D$4,1,0) -> #REF! | D14: =+IF(P.I!#REF!=P.I!$E$4,1,0) -> #REF! | E14: =+IF(P.I!#REF!=P.I!$F$4,1,0) -> #REF! | F14: =+IF(P.I!#REF!=P.I!$G$4,1,0) -> #REF! | G14: =+IF(P.I!#REF!=P.I!$H$4,1,0) -> #REF! | H14: =+IF(P.I!#REF!=P.I!$I$4,1,0) -> #REF! | I14: =+IF(P.I!#REF!=P.I!$J$4,1,0) -> #REF! | J14: =+IF(P.I!#REF!=P.I!$K$4,1,0) -> #REF! | K14: =+IF(P.I!#REF!=P.I!$L$4,1,0) -> #REF! | L14: =+IF(P.I!#REF!=P.I!$M$4,1,0) -> #REF! | M14: =+IF(P.I!#REF!=P.I!$N$4,1,0) -> #REF! | N14: =+IF(P.I!#REF!=P.I!$O$4,1,0) -> #REF! | O14: =+IF(P.I!#REF!=P.I!$P$4,1,0) -> #REF! | P14: =+IF(P.I!#REF!=P.I!$Q$4,1,0) -> #REF! | Q14: =+IF(P.I!#REF!=P.I!$R$4,1,0) -> #REF! | R14: =+IF(P.I!#REF!=P.I!$S$4,1,0) -> #REF! | S14: =+IF(P.I!#REF!=P.I!$T$4,1,0) -> #REF! | T14: =+IF(P.I!#REF!=P.I!$U$4,1,0) -> #REF! | U14: =+IF(P.I!#REF!=P.I!$V$4,1,0) -> #REF! | V14: =+IF(P.I!#REF!=P.I!$W$4,1,0) -> #REF! | W14: =+IF(P.I!#REF!=P.I!$X$4,1,0) -> #REF! | X14: =+IF(P.I!#REF!=P.I!$Y$4,1,0) -> #REF! | Y14: =+IF(P.I!#REF!=P.I!$Z$4,1,0) -> #REF! | Z14: =+IF(P.I!#REF!=P.I!$AA$4,1,0) -> #REF! | AA14: =+IF(P.I!#REF!=P.I!$AB$4,1,0) -> #REF! | AB14: =+IF(P.I!#REF!=P.I!$AC$4,1,0) -> #REF! | AC14: =+IF(P.I!#REF!=P.I!$AD$4,1,0) -> #REF! | AD14: =+IF(P.I!#REF!=P.I!$AE$4,1,0) -> #REF! | AE14: =+IF(P.I!#REF!=P.I!$AF$4,1,0) -> #REF! | AF14: =+IF(P.I!#REF!=P.I!$AG$4,1,0) -> #REF! | AG14: =+IF(P.I!#REF!=P.I!$AH$4,1,0) -> #REF! | AH14: =+IF(P.I!#REF!=P.I!$AI$4,1,0) -> #REF! | AI14: =+IF(P.I!#REF!=P.I!$AJ$4,1,0) -> #REF! | AJ14: =+IF(P.I!#REF!=P.I!$AK$4,1,0) -> #REF! | AK14: =+IF(P.I!#REF!=P.I!$AL$4,1,0) -> #REF! | AL14: =+IF(P.I!#REF!=P.I!$AM$4,1,0) -> #REF! | AM14: =+IF(P.I!#REF!=P.I!$AN$4,1,0) -> #REF! | AN14: =+IF(P.I!#REF!=P.I!$AO$4,1,0) -> #REF! | AO14: =+IF(P.I!#REF!=P.I!$AP$4,1,0) -> #REF! | AP14: =+IF(P.I!#REF!=P.I!$AQ$4,1,0) -> #REF! | AQ14: =+IF(P.I!#REF!=P.I!$AR$4,1,0) -> #REF! | AR14: =+IF(P.I!#REF!=P.I!$AS$4,1,0) -> #REF! | AS14: =+IF(P.I!#REF!=P.I!$AT$4,1,0) -> #REF! | AT14: =+IF(P.I!#REF!=P.I!$AU$4,1,0) -> #REF! | AU14: =+IF(P.I!#REF!=P.I!$AV$4,1,0) -> #REF! | AV14: =+IF(P.I!#REF!=P.I!$AW$4,1,0) -> #REF! | AW14: =+IF(P.I!#REF!=P.I!$AX$4,1,0) -> #REF! | AX14: =+IF(P.I!#REF!=P.I!$AY$4,1,0) -> #REF! | AY14: =+IF(P.I!#REF!=P.I!$AZ$4,1,0) -> #REF! | AZ14: =+IF(P.I!#REF!=P.I!$BA$4,1,0) -> #REF! | BA14: =+IF(P.I!#REF!=P.I!$BB$4,1,0) -> #REF! | BB14: =+IF(P.I!#REF!=P.I!$BC$4,1,0) -> #REF! | BC14: =+IF(P.I!#REF!=P.I!$BD$4,1,0) -> #REF! | BD14: =+IF(P.I!#REF!=P.I!$BE$4,1,0) -> #REF! | BE14: =+IF(P.I!#REF!=P.I!$BF$4,1,0) -> #REF! | BF14: =+IF(P.I!#REF!=P.I!$BG$4,1,0) -> #REF! | BG14: =+IF(P.I!#REF!=P.I!$BH$4,1,0) -> #REF! | BH14: =+IF(P.I!#REF!=P.I!$BI$4,1,0) -> #REF! | BI14: =+IF(P.I!#REF!=P.I!$BJ$4,1,0) -> #REF! | BJ14: =+IF(P.I!#REF!=P.I!$BK$4,1,0) -> #REF! | BK14: =+IF(P.I!#REF!=P.I!$BL$4,1,0) -> #REF! | BL14: =+IF(P.I!#REF!=P.I!$BM$4,1,0) -> #REF! | BM14: =+IF(P.I!#REF!=P.I!$BN$4,1,0) -> #REF! | BN14: =+IF(P.I!#REF!=P.I!$BO$4,1,0) -> #REF! | BO14: =+IF(P.I!#REF!=P.I!$BP$4,1,0) -> #REF! | BP14: =+IF(P.I!#REF!=P.I!$BQ$4,1,0) -> #REF! | BQ14: =+IF(P.I!#REF!=P.I!$BR$4,1,0) -> #REF! | BR14: =+IF(P.I!#REF!=P.I!$BS$4,1,0) -> #REF! | BS14: =+IF(P.I!#REF!=P.I!$BT$4,1,0) -> #REF! | BT14: =+IF(P.I!#REF!=P.I!$BU$4,1,0) -> #REF! | BU14: =+IF(P.I!#REF!=P.I!$BV$4,1,0) -> #REF! | BV14: =+IF(P.I!#REF!=P.I!$BW$4,1,0) -> #REF! | BW14: =+IF(P.I!#REF!=P.I!$BX$4,1,0) -> #REF! | BX14: =+IF(P.I!#REF!=P.I!$BY$4,1,0) -> #REF! | BY14: =+IF(P.I!#REF!=P.I!$BZ$4,1,0) -> #REF! | BZ14: =+IF(P.I!#REF!=P.I!$CA$4,1,0) -> #REF! | CA14: =+IF(P.I!#REF!=P.I!$CB$4,1,0) -> #REF! | CB14: =+IF(P.I!#REF!=P.I!$CC$4,1,0) -> #REF! | CC14: =+IF(P.I!#REF!=P.I!$CD$4,1,0) -> #REF! | CD14: =+IF(P.I!#REF!=P.I!$CE$4,1,0) -> #REF! | CE14: =+SUM(C14:AP14) -> #REF! | CF14: =+CE14/$CF$3*100 -> #REF! | CG14: =+CF14*5/100 -> #REF! | CH14: =+SUM(AQ14:CD14) -> #REF! | CI14: =+CH14/$CI$3*100 -> #REF! | CJ14: =+CI14*5/100 -> #REF! | CK14: =+CE14+CH14 -> #REF! | CL14: =+CK14/$CL$3*100 -> #REF! | CM14: =+CL14*5/100 -> #REF!
A15: 11 | B15: =P.I!C27 -> JUNIOR ANDRES CALLE SAMARRA | C15: =+IF(P.I!D27=P.I!$D$4,1,0) -> 0 | D15: =+IF(P.I!E27=P.I!$E$4,1,0) -> 0 | E15: =+IF(P.I!F27=P.I!$F$4,1,0) -> 0 | F15: =+IF(P.I!G27=P.I!$G$4,1,0) -> 0 | G15: =+IF(P.I!H27=P.I!$H$4,1,0) -> 0 | H15: =+IF(P.I!I27=P.I!$I$4,1,0) -> 0 | I15: =+IF(P.I!J27=P.I!$J$4,1,0) -> 0 | J15: =+IF(P.I!K27=P.I!$K$4,1,0) -> 0 | K15: =+IF(P.I!L27=P.I!$L$4,1,0) -> 0 | L15: =+IF(P.I!M27=P.I!$M$4,1,0) -> 0 | M15: =+IF(P.I!N27=P.I!$N$4,1,0) -> 0 | N15: =+IF(P.I!O27=P.I!$O$4,1,0) -> 0 | O15: =+IF(P.I!P27=P.I!$P$4,1,0) -> 0 | P15: =+IF(P.I!Q27=P.I!$Q$4,1,0) -> 0 | Q15: =+IF(P.I!R27=P.I!$R$4,1,0) -> 0 | R15: =+IF(P.I!S27=P.I!$S$4,1,0) -> 0 | S15: =+IF(P.I!T27=P.I!$T$4,1,0) -> 0 | T15: =+IF(P.I!U27=P.I!$U$4,1,0) -> 0 | U15: =+IF(P.I!V27=P.I!$V$4,1,0) -> 0 | V15: =+IF(P.I!W27=P.I!$W$4,1,0) -> 0 | W15: =+IF(P.I!X27=P.I!$X$4,1,0) -> 0 | X15: =+IF(P.I!Y27=P.I!$Y$4,1,0) -> 0 | Y15: =+IF(P.I!Z27=P.I!$Z$4,1,0) -> 0 | Z15: =+IF(P.I!AA27=P.I!$AA$4,1,0) -> 0 | AA15: =+IF(P.I!AB27=P.I!$AB$4,1,0) -> 0 | AB15: =+IF(P.I!AC27=P.I!$AC$4,1,0) -> 0 | AC15: =+IF(P.I!AD27=P.I!$AD$4,1,0) -> 0 | AD15: =+IF(P.I!AE27=P.I!$AE$4,1,0) -> 0 | AE15: =+IF(P.I!AF27=P.I!$AF$4,1,0) -> 0 | AF15: =+IF(P.I!AG27=P.I!$AG$4,1,0) -> 0 | AG15: =+IF(P.I!AH27=P.I!$AH$4,1,0) -> 0 | AH15: =+IF(P.I!AI27=P.I!$AI$4,1,0) -> 0 | AI15: =+IF(P.I!AJ27=P.I!$AJ$4,1,0) -> 0 | AJ15: =+IF(P.I!AK27=P.I!$AK$4,1,0) -> 0 | AK15: =+IF(P.I!AL27=P.I!$AL$4,1,0) -> 0 | AL15: =+IF(P.I!AM27=P.I!$AM$4,1,0) -> 0 | AM15: =+IF(P.I!AN27=P.I!$AN$4,1,0) -> 0 | AN15: =+IF(P.I!AO27=P.I!$AO$4,1,0) -> 0 | AO15: =+IF(P.I!AP27=P.I!$AP$4,1,0) -> 0 | AP15: =+IF(P.I!AQ27=P.I!$AQ$4,1,0) -> 0 | AQ15: =+IF(P.I!AR27=P.I!$AR$4,1,0) -> 0 | AR15: =+IF(P.I!AS27=P.I!$AS$4,1,0) -> 0 | AS15: =+IF(P.I!AT27=P.I!$AT$4,1,0) -> 1 | AT15: =+IF(P.I!AU27=P.I!$AU$4,1,0) -> 0 | AU15: =+IF(P.I!AV27=P.I!$AV$4,1,0) -> 0 | AV15: =+IF(P.I!AW27=P.I!$AW$4,1,0) -> 0 | AW15: =+IF(P.I!AX27=P.I!$AX$4,1,0) -> 0 | AX15: =+IF(P.I!AY27=P.I!$AY$4,1,0) -> 1 | AY15: =+IF(P.I!AZ27=P.I!$AZ$4,1,0) -> 1 | AZ15: =+IF(P.I!BA27=P.I!$BA$4,1,0) -> 1 | BA15: =+IF(P.I!BB27=P.I!$BB$4,1,0) -> 0 | BB15: =+IF(P.I!BC27=P.I!$BC$4,1,0) -> 1 | BC15: =+IF(P.I!BD27=P.I!$BD$4,1,0) -> 0 | BD15: =+IF(P.I!BE27=P.I!$BE$4,1,0) -> 1 | BE15: =+IF(P.I!BF27=P.I!$BF$4,1,0) -> 0 | BF15: =+IF(P.I!BG27=P.I!$BG$4,1,0) -> 0 | BG15: =+IF(P.I!BH27=P.I!$BH$4,1,0) -> 0 | BH15: =+IF(P.I!BI27=P.I!$BI$4,1,0) -> 1 | BI15: =+IF(P.I!BJ27=P.I!$BJ$4,1,0) -> 0 | BJ15: =+IF(P.I!BK27=P.I!$BK$4,1,0) -> 1 | BK15: =+IF(P.I!BL27=P.I!$BL$4,1,0) -> 0 | BL15: =+IF(P.I!BM27=P.I!$BM$4,1,0) -> 1 | BM15: =+IF(P.I!BN27=P.I!$BN$4,1,0) -> 0 | BN15: =+IF(P.I!BO27=P.I!$BO$4,1,0) -> 0 | BO15: =+IF(P.I!BP27=P.I!$BP$4,1,0) -> 0 | BP15: =+IF(P.I!BQ27=P.I!$BQ$4,1,0) -> 1 | BQ15: =+IF(P.I!BR27=P.I!$BR$4,1,0) -> 0 | BR15: =+IF(P.I!BS27=P.I!$BS$4,1,0) -> 0 | BS15: =+IF(P.I!BT27=P.I!$BT$4,1,0) -> 0 | BT15: =+IF(P.I!BU27=P.I!$BU$4,1,0) -> 0 | BU15: =+IF(P.I!BV27=P.I!$BV$4,1,0) -> 0 | BV15: =+IF(P.I!BW27=P.I!$BW$4,1,0) -> 0 | BW15: =+IF(P.I!BX27=P.I!$BX$4,1,0) -> 0 | BX15: =+IF(P.I!BY27=P.I!$BY$4,1,0) -> 1 | BY15: =+IF(P.I!BZ27=P.I!$BZ$4,1,0) -> 0 | BZ15: =+IF(P.I!CA27=P.I!$CA$4,1,0) -> 0 | CA15: =+IF(P.I!CB27=P.I!$CB$4,1,0) -> 0 | CB15: =+IF(P.I!CC27=P.I!$CC$4,1,0) -> 1 | CC15: =+IF(P.I!CD27=P.I!$CD$4,1,0) -> 0 | CD15: =+IF(P.I!CE27=P.I!$CE$4,1,0) -> 0 | CE15: =+SUM(C15:AP15) -> 0 | CF15: =+CE15/$CF$3*100 -> 0 | CG15: =+CF15*5/100 -> 0 | CH15: =+SUM(AQ15:CD15) -> 12 | CI15: =+CH15/$CI$3*100 -> 31.578947 | CJ15: =+CI15*5/100 -> 1.5789474 | CK15: =+CE15+CH15 -> 12 | CL15: =+CK15/$CL$3*100 -> 15.584416 | CM15: =+CL15*5/100 -> 0.77922078
A16: 12 | B16: =P.I!C28 -> KAREN NOEMITH NIETO DE AGUAS | C16: =+IF(P.I!D28=P.I!$D$4,1,0) -> 0 | D16: =+IF(P.I!E28=P.I!$E$4,1,0) -> 0 | E16: =+IF(P.I!F28=P.I!$F$4,1,0) -> 0 | F16: =+IF(P.I!G28=P.I!$G$4,1,0) -> 0 | G16: =+IF(P.I!H28=P.I!$H$4,1,0) -> 0 | H16: =+IF(P.I!I28=P.I!$I$4,1,0) -> 0 | I16: =+IF(P.I!J28=P.I!$J$4,1,0) -> 0 | J16: =+IF(P.I!K28=P.I!$K$4,1,0) -> 0 | K16: =+IF(P.I!L28=P.I!$L$4,1,0) -> 0 | L16: =+IF(P.I!M28=P.I!$M$4,1,0) -> 0 | M16: =+IF(P.I!N28=P.I!$N$4,1,0) -> 0 | N16: =+IF(P.I!O28=P.I!$O$4,1,0) -> 0 | O16: =+IF(P.I!P28=P.I!$P$4,1,0) -> 0 | P16: =+IF(P.I!Q28=P.I!$Q$4,1,0) -> 0 | Q16: =+IF(P.I!R28=P.I!$R$4,1,0) -> 0 | R16: =+IF(P.I!S28=P.I!$S$4,1,0) -> 0 | S16: =+IF(P.I!T28=P.I!$T$4,1,0) -> 0 | T16: =+IF(P.I!U28=P.I!$U$4,1,0) -> 0 | U16: =+IF(P.I!V28=P.I!$V$4,1,0) -> 0 | V16: =+IF(P.I!W28=P.I!$W$4,1,0) -> 0 | W16: =+IF(P.I!X28=P.I!$X$4,1,0) -> 0 | X16: =+IF(P.I!Y28=P.I!$Y$4,1,0) -> 0 | Y16: =+IF(P.I!Z28=P.I!$Z$4,1,0) -> 0 | Z16: =+IF(P.I!AA28=P.I!$AA$4,1,0) -> 0 | AA16: =+IF(P.I!AB28=P.I!$AB$4,1,0) -> 0 | AB16: =+IF(P.I!AC28=P.I!$AC$4,1,0) -> 0 | AC16: =+IF(P.I!AD28=P.I!$AD$4,1,0) -> 0 | AD16: =+IF(P.I!AE28=P.I!$AE$4,1,0) -> 0 | AE16: =+IF(P.I!AF28=P.I!$AF$4,1,0) -> 0 | AF16: =+IF(P.I!AG28=P.I!$AG$4,1,0) -> 0 | AG16: =+IF(P.I!AH28=P.I!$AH$4,1,0) -> 0 | AH16: =+IF(P.I!AI28=P.I!$AI$4,1,0) -> 0 | AI16: =+IF(P.I!AJ28=P.I!$AJ$4,1,0) -> 0 | AJ16: =+IF(P.I!AK28=P.I!$AK$4,1,0) -> 0 | AK16: =+IF(P.I!AL28=P.I!$AL$4,1,0) -> 0 | AL16: =+IF(P.I!AM28=P.I!$AM$4,1,0) -> 0 | AM16: =+IF(P.I!AN28=P.I!$AN$4,1,0) -> 0 | AN16: =+IF(P.I!AO28=P.I!$AO$4,1,0) -> 0 | AO16: =+IF(P.I!AP28=P.I!$AP$4,1,0) -> 0 | AP16: =+IF(P.I!AQ28=P.I!$AQ$4,1,0) -> 0 | AQ16: =+IF(P.I!AR28=P.I!$AR$4,1,0) -> 1 | AR16: =+IF(P.I!AS28=P.I!$AS$4,1,0) -> 0 | AS16: =+IF(P.I!AT28=P.I!$AT$4,1,0) -> 0 | AT16: =+IF(P.I!AU28=P.I!$AU$4,1,0) -> 0 | AU16: =+IF(P.I!AV28=P.I!$AV$4,1,0) -> 0 | AV16: =+IF(P.I!AW28=P.I!$AW$4,1,0) -> 1 | AW16: =+IF(P.I!AX28=P.I!$AX$4,1,0) -> 1 | AX16: =+IF(P.I!AY28=P.I!$AY$4,1,0) -> 1 | AY16: =+IF(P.I!AZ28=P.I!$AZ$4,1,0) -> 0 | AZ16: =+IF(P.I!BA28=P.I!$BA$4,1,0) -> 0 | BA16: =+IF(P.I!BB28=P.I!$BB$4,1,0) -> 0 | BB16: =+IF(P.I!BC28=P.I!$BC$4,1,0) -> 0 | BC16: =+IF(P.I!BD28=P.I!$BD$4,1,0) -> 1 | BD16: =+IF(P.I!BE28=P.I!$BE$4,1,0) -> 0 | BE16: =+IF(P.I!BF28=P.I!$BF$4,1,0) -> 0 | BF16: =+IF(P.I!BG28=P.I!$BG$4,1,0) -> 0 | BG16: =+IF(P.I!BH28=P.I!$BH$4,1,0) -> 1 | BH16: =+IF(P.I!BI28=P.I!$BI$4,1,0) -> 1 | BI16: =+IF(P.I!BJ28=P.I!$BJ$4,1,0) -> 0 | BJ16: =+IF(P.I!BK28=P.I!$BK$4,1,0) -> 1 | BK16: =+IF(P.I!BL28=P.I!$BL$4,1,0) -> 1 | BL16: =+IF(P.I!BM28=P.I!$BM$4,1,0) -> 0 | BM16: =+IF(P.I!BN28=P.I!$BN$4,1,0) -> 0 | BN16: =+IF(P.I!BO28=P.I!$BO$4,1,0) -> 0 | BO16: =+IF(P.I!BP28=P.I!$BP$4,1,0) -> 0 | BP16: =+IF(P.I!BQ28=P.I!$BQ$4,1,0) -> 0 | BQ16: =+IF(P.I!BR28=P.I!$BR$4,1,0) -> 0 | BR16: =+IF(P.I!BS28=P.I!$BS$4,1,0) -> 1 | BS16: =+IF(P.I!BT28=P.I!$BT$4,1,0) -> 0 | BT16: =+IF(P.I!BU28=P.I!$BU$4,1,0) -> 0 | BU16: =+IF(P.I!BV28=P.I!$BV$4,1,0) -> 1 | BV16: =+IF(P.I!BW28=P.I!$BW$4,1,0) -> 0 | BW16: =+IF(P.I!BX28=P.I!$BX$4,1,0) -> 0 | BX16: =+IF(P.I!BY28=P.I!$BY$4,1,0) -> 1 | BY16: =+IF(P.I!BZ28=P.I!$BZ$4,1,0) -> 1 | BZ16: =+IF(P.I!CA28=P.I!$CA$4,1,0) -> 0 | CA16: =+IF(P.I!CB28=P.I!$CB$4,1,0) -> 1 | CB16: =+IF(P.I!CC28=P.I!$CC$4,1,0) -> 1 | CC16: =+IF(P.I!CD28=P.I!$CD$4,1,0) -> 0 | CD16: =+IF(P.I!CE28=P.I!$CE$4,1,0) -> 0 | CE16: =+SUM(C16:AP16) -> 0 | CF16: =+CE16/$CF$3*100 -> 0 | CG16: =+CF16*5/100 -> 0 | CH16: =+SUM(AQ16:CD16) -> 15 | CI16: =+CH16/$CI$3*100 -> 39.473684 | CJ16: =+CI16*5/100 -> 1.9736842 | CK16: =+CE16+CH16 -> 15 | CL16: =+CK16/$CL$3*100 -> 19.480519 | CM16: =+CL16*5/100 -> 0.97402597
